<?xml version="1.0" ?>
<robot name="LeRemix" xmlns:xacro="http://www.ros.org/wiki/xacro">

<xacro:include filename="$(find leremix_description)/urdf/materials.xacro" />

<link name="base_link">
  <inertial>
    <origin xyz="5.866413998148801e-05 0.0062819967824381704 0.001416599330144379" rpy="0 0 0"/>
    <mass value="0.8949198281645031"/>
    <inertia ixx="0.003064" iyy="0.002933" izz="0.005996" ixy="-2e-06" iyz="0.0" ixz="0.0"/>
  </inertial>
  <visual>
    <origin xyz="0 0 0" rpy="0 0 0"/>
    <geometry>
      <mesh filename="file://$(find leremix_description)/meshes/base_link.stl" scale="0.001 0.001 0.001"/>
    </geometry>
    <material name="silver"/>
  </visual>
  <collision>
    <origin xyz="0 0 0" rpy="0 0 0"/>
    <geometry>
      <mesh filename="file://$(find leremix_description)/meshes/base_link.stl" scale="0.001 0.001 0.001"/>
    </geometry>
  </collision>
</link>

<link name="arm_base_rotation_servo_1">
  <inertial>
    <origin xyz="0.019999044959765788 0.01025034011227997 0.016027263585011595" rpy="0 0 0"/>
    <mass value="0.2843033831904074"/>
    <inertia ixx="4e-05" iyy="7.3e-05" izz="6.2e-05" ixy="0.0" iyz="0.0" ixz="-1e-06"/>
  </inertial>
  <visual>
    <origin xyz="-0.050662 0.004002 -0.083133" rpy="0 0 0"/>
    <geometry>
      <mesh filename="file://$(find leremix_description)/meshes/arm_base_rotation_servo_1.stl" scale="0.001 0.001 0.001"/>
    </geometry>
    <material name="silver"/>
  </visual>
  <collision>
    <origin xyz="-0.050662 0.004002 -0.083133" rpy="0 0 0"/>
    <geometry>
      <mesh filename="file://$(find leremix_description)/meshes/arm_base_rotation_servo_1.stl" scale="0.001 0.001 0.001"/>
    </geometry>
  </collision>
</link>

<link name="arm_base_rotation_link_1">
  <inertial>
    <origin xyz="0.03155588382289583 -0.00027122946045804366 -0.009540250989642243" rpy="0 0 0"/>
    <mass value="0.5385469320676795"/>
    <inertia ixx="0.000341" iyy="0.000375" izz="0.000154" ixy="-1e-06" iyz="3e-06" ixz="-3.6e-05"/>
  </inertial>
  <visual>
    <origin xyz="-0.083462 -0.006248 -0.117733" rpy="0 0 0"/>
    <geometry>
      <mesh filename="file://$(find leremix_description)/meshes/arm_base_rotation_link_1.stl" scale="0.001 0.001 0.001"/>
    </geometry>
    <material name="silver"/>
  </visual>
  <collision>
    <origin xyz="-0.083462 -0.006248 -0.117733" rpy="0 0 0"/>
    <geometry>
      <mesh filename="file://$(find leremix_description)/meshes/arm_base_rotation_link_1.stl" scale="0.001 0.001 0.001"/>
    </geometry>
  </collision>
</link>

<link name="arm_base_rotation_link_cover_1">
  <inertial>
    <origin xyz="-0.009494213831683473 0.023250133340888265 -0.002658011177624875" rpy="0 0 0"/>
    <mass value="0.10853073755546007"/>
    <inertia ixx="4.6e-05" iyy="2.7e-05" izz="5.8e-05" ixy="-0.0" iyz="-0.0" ixz="-0.0"/>
  </inertial>
  <visual>
    <origin xyz="-0.124312 0.016752 -0.140933" rpy="0 0 0"/>
    <geometry>
      <mesh filename="file://$(find leremix_description)/meshes/arm_base_rotation_link_cover_1.stl" scale="0.001 0.001 0.001"/>
    </geometry>
    <material name="silver"/>
  </visual>
  <collision>
    <origin xyz="-0.124312 0.016752 -0.140933" rpy="0 0 0"/>
    <geometry>
      <mesh filename="file://$(find leremix_description)/meshes/arm_base_rotation_link_cover_1.stl" scale="0.001 0.001 0.001"/>
    </geometry>
  </collision>
</link>

<link name="arm_shoulder_servo_1">
  <inertial>
    <origin xyz="-0.010249982610195635 -0.016026724819197403 0.019999226223505806" rpy="0 0 0"/>
    <mass value="0.2843033831904074"/>
    <inertia ixx="7.3e-05" iyy="6.2e-05" izz="4e-05" ixy="0.0" iyz="1e-06" ixz="-0.0"/>
  </inertial>
  <visual>
    <origin xyz="-0.124312 -0.022548 -0.137133" rpy="0 0 0"/>
    <geometry>
      <mesh filename="file://$(find leremix_description)/meshes/arm_shoulder_servo_1.stl" scale="0.001 0.001 0.001"/>
    </geometry>
    <material name="silver"/>
  </visual>
  <collision>
    <origin xyz="-0.124312 -0.022548 -0.137133" rpy="0 0 0"/>
    <geometry>
      <mesh filename="file://$(find leremix_description)/meshes/arm_shoulder_servo_1.stl" scale="0.001 0.001 0.001"/>
    </geometry>
  </collision>
</link>

<link name="arm_shoulder_link_1">
  <inertial>
    <origin xyz="-0.055943188746678085 0.01969986419355535 -0.015368056226457844" rpy="0 0 0"/>
    <mass value="0.9906249126045027"/>
    <inertia ixx="0.000563" iyy="0.001251" izz="0.001549" ixy="-8e-06" iyz="-3e-06" ixz="-0.000304"/>
  </inertial>
  <visual>
    <origin xyz="-0.114062 0.012052 -0.169933" rpy="0 0 0"/>
    <geometry>
      <mesh filename="file://$(find leremix_description)/meshes/arm_shoulder_link_1.stl" scale="0.001 0.001 0.001"/>
    </geometry>
    <material name="silver"/>
  </visual>
  <collision>
    <origin xyz="-0.114062 0.012052 -0.169933" rpy="0 0 0"/>
    <geometry>
      <mesh filename="file://$(find leremix_description)/meshes/arm_shoulder_link_1.stl" scale="0.001 0.001 0.001"/>
    </geometry>
  </collision>
</link>

<link name="arm_elbow_servo_1">
  <inertial>
    <origin xyz="-0.015077029653089111 -0.016026724819193545 0.016665077642131626" rpy="0 0 0"/>
    <mass value="0.2843033831904074"/>
    <inertia ixx="7.1e-05" iyy="6.2e-05" izz="4.2e-05" ixy="-0.0" iyz="1e-06" ixz="8e-06"/>
  </inertial>
  <visual>
    <origin xyz="-0.016471 -0.024048 -0.138814" rpy="0 0 0"/>
    <geometry>
      <mesh filename="file://$(find leremix_description)/meshes/arm_elbow_servo_1.stl" scale="0.001 0.001 0.001"/>
    </geometry>
    <material name="silver"/>
  </visual>
  <collision>
    <origin xyz="-0.016471 -0.024048 -0.138814" rpy="0 0 0"/>
    <geometry>
      <mesh filename="file://$(find leremix_description)/meshes/arm_elbow_servo_1.stl" scale="0.001 0.001 0.001"/>
    </geometry>
  </collision>
</link>

<link name="arm_elbow_link_1">
  <inertial>
    <origin xyz="0.05832613508152747 0.015215218913568064 0.02137713488564641" rpy="0 0 0"/>
    <mass value="0.8772447501056027"/>
    <inertia ixx="0.000473" iyy="0.000993" izz="0.001135" ixy="-0.000109" iyz="-4.1e-05" ixz="-0.000289"/>
  </inertial>
  <visual>
    <origin xyz="0.001919 0.010552 -0.167844" rpy="0 0 0"/>
    <geometry>
      <mesh filename="file://$(find leremix_description)/meshes/arm_elbow_link_1.stl" scale="0.001 0.001 0.001"/>
    </geometry>
    <material name="silver"/>
  </visual>
  <collision>
    <origin xyz="0.001919 0.010552 -0.167844" rpy="0 0 0"/>
    <geometry>
      <mesh filename="file://$(find leremix_description)/meshes/arm_elbow_link_1.stl" scale="0.001 0.001 0.001"/>
    </geometry>
  </collision>
</link>

<link name="arm_wrist_tilt_servo_1">
  <inertial>
    <origin xyz="0.021970231163924825 -0.016026724819192876 -0.004724278591325293" rpy="0 0 0"/>
    <mass value="0.2843033831904074"/>
    <inertia ixx="4.2e-05" iyy="6.2e-05" izz="7.1e-05" ixy="1e-06" iyz="0.0" ixz="-8e-06"/>
  </inertial>
  <visual>
    <origin xyz="-0.089679 -0.025548 -0.217624" rpy="0 0 0"/>
    <geometry>
      <mesh filename="file://$(find leremix_description)/meshes/arm_wrist_tilt_servo_1.stl" scale="0.001 0.001 0.001"/>
    </geometry>
    <material name="silver"/>
  </visual>
  <collision>
    <origin xyz="-0.089679 -0.025548 -0.217624" rpy="0 0 0"/>
    <geometry>
      <mesh filename="file://$(find leremix_description)/meshes/arm_wrist_tilt_servo_1.stl" scale="0.001 0.001 0.001"/>
    </geometry>
  </collision>
</link>

<link name="arm_wrist_link_1">
  <inertial>
    <origin xyz="0.012975594362619927 0.016810121377602565 -0.02296834504128556" rpy="0 0 0"/>
    <mass value="0.2392168278135931"/>
    <inertia ixx="0.000182" iyy="0.000115" izz="0.000144" ixy="3e-06" iyz="-6e-06" ixz="3.2e-05"/>
  </inertial>
  <visual>
    <origin xyz="-0.124014 0.009052 -0.216213" rpy="0 0 0"/>
    <geometry>
      <mesh filename="file://$(find leremix_description)/meshes/arm_wrist_link_1.stl" scale="0.001 0.001 0.001"/>
    </geometry>
    <material name="silver"/>
  </visual>
  <collision>
    <origin xyz="-0.124014 0.009052 -0.216213" rpy="0 0 0"/>
    <geometry>
      <mesh filename="file://$(find leremix_description)/meshes/arm_wrist_link_1.stl" scale="0.001 0.001 0.001"/>
    </geometry>
  </collision>
</link>

<link name="arm_wrist_roll_servo_1">
  <inertial>
    <origin xyz="-0.01656958325728916 0.015998644972749377 0.008429716426542305" rpy="0 0 0"/>
    <mass value="0.2799142523131049"/>
    <inertia ixx="6.9e-05" iyy="3.8e-05" izz="6.3e-05" ixy="-1e-06" iyz="1e-06" ixz="5e-06"/>
  </inertial>
  <visual>
    <origin xyz="-0.161703 0.017952 -0.170568" rpy="0 0 0"/>
    <geometry>
      <mesh filename="file://$(find leremix_description)/meshes/arm_wrist_roll_servo_1.stl" scale="0.001 0.001 0.001"/>
    </geometry>
    <material name="silver"/>
  </visual>
  <collision>
    <origin xyz="-0.161703 0.017952 -0.170568" rpy="0 0 0"/>
    <geometry>
      <mesh filename="file://$(find leremix_description)/meshes/arm_wrist_roll_servo_1.stl" scale="0.001 0.001 0.001"/>
    </geometry>
  </collision>
</link>

<link name="arm_gripper_1">
  <inertial>
    <origin xyz="0.013339671966003358 -0.013714806926169776 -0.026125553965198" rpy="0 0 0"/>
    <mass value="0.44698022927880193"/>
    <inertia ixx="0.000294" iyy="0.000301" izz="0.000205" ixy="3e-05" iyz="-4.7e-05" ixz="7.1e-05"/>
  </inertial>
  <visual>
    <origin xyz="-0.15417 -0.011048 -0.163073" rpy="0 0 0"/>
    <geometry>
      <mesh filename="file://$(find leremix_description)/meshes/arm_gripper_1.stl" scale="0.001 0.001 0.001"/>
    </geometry>
    <material name="silver"/>
  </visual>
  <collision>
    <origin xyz="-0.15417 -0.011048 -0.163073" rpy="0 0 0"/>
    <geometry>
      <mesh filename="file://$(find leremix_description)/meshes/arm_gripper_1.stl" scale="0.001 0.001 0.001"/>
    </geometry>
  </collision>
</link>

<link name="arm_gripper_servo_1">
  <inertial>
    <origin xyz="-0.007975468163954197 0.020789656863227802 -0.01631207348591407" rpy="0 0 0"/>
    <mass value="0.2843033831904074"/>
    <inertia ixx="6.4e-05" iyy="4e-05" izz="7.1e-05" ixy="-0.0" iyz="-0.0" ixz="-5e-06"/>
  </inertial>
  <visual>
    <origin xyz="-0.173846 0.00275 -0.159436" rpy="0 0 0"/>
    <geometry>
      <mesh filename="file://$(find leremix_description)/meshes/arm_gripper_servo_1.stl" scale="0.001 0.001 0.001"/>
    </geometry>
    <material name="silver"/>
  </visual>
  <collision>
    <origin xyz="-0.173846 0.00275 -0.159436" rpy="0 0 0"/>
    <geometry>
      <mesh filename="file://$(find leremix_description)/meshes/arm_gripper_servo_1.stl" scale="0.001 0.001 0.001"/>
    </geometry>
  </collision>
</link>

<link name="arm_jaw_1">
  <inertial>
    <origin xyz="0.032905631581261585 -0.003660190112443975 -0.016197173267020665" rpy="0 0 0"/>
    <mass value="0.1586808414280307"/>
    <inertia ixx="6.1e-05" iyy="8.6e-05" izz="3.4e-05" ixy="4e-06" iyz="-5e-06" ixz="1.9e-05"/>
  </inertial>
  <visual>
    <origin xyz="-0.150306 -0.03177 -0.134291" rpy="0 0 0"/>
    <geometry>
      <mesh filename="file://$(find leremix_description)/meshes/arm_jaw_1.stl" scale="0.001 0.001 0.001"/>
    </geometry>
    <material name="silver"/>
  </visual>
  <collision>
    <origin xyz="-0.150306 -0.03177 -0.134291" rpy="0 0 0"/>
    <geometry>
      <mesh filename="file://$(find leremix_description)/meshes/arm_jaw_1.stl" scale="0.001 0.001 0.001"/>
    </geometry>
  </collision>
</link>

<link name="right_servo_mount_1">
  <inertial>
    <origin xyz="0.02008674389712354 0.005193645092054736 0.023611795909587813" rpy="0 0 0"/>
    <mass value="0.14423806644766202"/>
    <inertia ixx="5.5e-05" iyy="6.4e-05" izz="5.3e-05" ixy="-8e-06" iyz="-1e-06" ixz="1e-06"/>
  </inertial>
  <visual>
    <origin xyz="-0.028994 0.073033 -0.002833" rpy="0 0 0"/>
    <geometry>
      <mesh filename="file://$(find leremix_description)/meshes/right_servo_mount_1.stl" scale="0.001 0.001 0.001"/>
    </geometry>
    <material name="silver"/>
  </visual>
  <collision>
    <origin xyz="-0.028994 0.073033 -0.002833" rpy="0 0 0"/>
    <geometry>
      <mesh filename="file://$(find leremix_description)/meshes/right_servo_mount_1.stl" scale="0.001 0.001 0.001"/>
    </geometry>
  </collision>
</link>

<link name="right_servo_1">
  <inertial>
    <origin xyz="0.016946033965199135 -0.008868786547698113 0.0048191214240031685" rpy="0 0 0"/>
    <mass value="0.27778201352216375"/>
    <inertia ixx="6.8e-05" iyy="6.3e-05" izz="3.8e-05" ixy="4e-06" iyz="-1e-06" ixz="1e-06"/>
  </inertial>
  <visual>
    <origin xyz="-0.034659 0.063359 -0.021333" rpy="0 0 0"/>
    <geometry>
      <mesh filename="file://$(find leremix_description)/meshes/right_servo_1.stl" scale="0.001 0.001 0.001"/>
    </geometry>
    <material name="silver"/>
  </visual>
  <collision>
    <origin xyz="-0.034659 0.063359 -0.021333" rpy="0 0 0"/>
    <geometry>
      <mesh filename="file://$(find leremix_description)/meshes/right_servo_1.stl" scale="0.001 0.001 0.001"/>
    </geometry>
  </collision>
</link>

<link name="right_wheel_mount_1">
  <inertial>
    <origin xyz="0.002761073890032273 -0.004782787911662353 -3.6033637842991517e-07" rpy="0 0 0"/>
    <mass value="0.1235708646349694"/>
    <inertia ixx="2.2e-05" iyy="2.9e-05" izz="1.8e-05" ixy="-6e-06" iyz="0.0" ixz="0.0"/>
  </inertial>
  <visual>
    <origin xyz="-0.060348 0.087326 -0.013051" rpy="0 0 0"/>
    <geometry>
      <mesh filename="file://$(find leremix_description)/meshes/right_wheel_mount_1.stl" scale="0.001 0.001 0.001"/>
    </geometry>
    <material name="silver"/>
  </visual>
  <collision>
    <origin xyz="-0.060348 0.087326 -0.013051" rpy="0 0 0"/>
    <geometry>
      <mesh filename="file://$(find leremix_description)/meshes/right_wheel_mount_1.stl" scale="0.001 0.001 0.001"/>
    </geometry>
  </collision>
</link>

<link name="back_servo_mount_1">
  <inertial>
    <origin xyz="0.015077241076461259 0.02000648709955183 0.023640282718459048" rpy="0 0 0"/>
    <mass value="0.13962178083501173"/>
    <inertia ixx="6.6e-05" iyy="4.7e-05" izz="5e-05" ixy="-0.0" iyz="0.0" ixz="-2e-06"/>
  </inertial>
  <visual>
    <origin xyz="0.093686 0.013751 -0.002833" rpy="0 0 0"/>
    <geometry>
      <mesh filename="file://$(find leremix_description)/meshes/back_servo_mount_1.stl" scale="0.001 0.001 0.001"/>
    </geometry>
    <material name="silver"/>
  </visual>
  <collision>
    <origin xyz="0.093686 0.013751 -0.002833" rpy="0 0 0"/>
    <geometry>
      <mesh filename="file://$(find leremix_description)/meshes/back_servo_mount_1.stl" scale="0.001 0.001 0.001"/>
    </geometry>
  </collision>
</link>

<link name="left_servo_mount_1">
  <inertial>
    <origin xyz="0.009786012594139637 -0.023059797468141602 0.023640282726657757" rpy="0 0 0"/>
    <mass value="0.13962178077674334"/>
    <inertia ixx="5.2e-05" iyy="6.2e-05" izz="5e-05" ixy="8e-06" iyz="1e-06" ixz="1e-06"/>
  </inertial>
  <visual>
    <origin xyz="-0.038994 -0.102851 -0.002833" rpy="0 0 0"/>
    <geometry>
      <mesh filename="file://$(find leremix_description)/meshes/left_servo_mount_1.stl" scale="0.001 0.001 0.001"/>
    </geometry>
    <material name="silver"/>
  </visual>
  <collision>
    <origin xyz="-0.038994 -0.102851 -0.002833" rpy="0 0 0"/>
    <geometry>
      <mesh filename="file://$(find leremix_description)/meshes/left_servo_mount_1.stl" scale="0.001 0.001 0.001"/>
    </geometry>
  </collision>
</link>

<link name="back_servo_1">
  <inertial>
    <origin xyz="-0.016153032440181764 -0.010249777894134756 -0.019698916271482823" rpy="0 0 0"/>
    <mass value="0.2777820135235829"/>
    <inertia ixx="6e-05" iyy="7e-05" izz="3.8e-05" ixy="-0.0" iyz="-0.0" ixz="-1e-06"/>
  </inertial>
  <visual>
    <origin xyz="0.068141 -0.016505 -0.045832" rpy="0 0 0"/>
    <geometry>
      <mesh filename="file://$(find leremix_description)/meshes/back_servo_1.stl" scale="0.001 0.001 0.001"/>
    </geometry>
    <material name="silver"/>
  </visual>
  <collision>
    <origin xyz="0.068141 -0.016505 -0.045832" rpy="0 0 0"/>
    <geometry>
      <mesh filename="file://$(find leremix_description)/meshes/back_servo_1.stl" scale="0.001 0.001 0.001"/>
    </geometry>
  </collision>
</link>

<link name="right_wheel_1">
  <inertial>
    <origin xyz="0.007687527486229681 -0.0133147596761716 -4.2527541098749677e-07" rpy="0 0 0"/>
    <mass value="1.3542854082324305"/>
    <inertia ixx="0.00129" iyy="0.001683" izz="0.001094" ixy="-0.00034" iyz="-0.0" ixz="-0.0"/>
  </inertial>
  <visual>
    <origin xyz="-0.063935 0.09354 -0.013051" rpy="0 0 0"/>
    <geometry>
      <mesh filename="file://$(find leremix_description)/meshes/right_wheel_1.stl" scale="0.001 0.001 0.001"/>
    </geometry>
    <material name="silver"/>
  </visual>
  <collision>
    <origin xyz="-0.063935 0.09354 -0.013051" rpy="0 0 0"/>
    <geometry>
      <mesh filename="file://$(find leremix_description)/meshes/right_wheel_1.stl" scale="0.001 0.001 0.001"/>
    </geometry>
  </collision>
</link>

<link name="back_wheel_mount_1">
  <inertial>
    <origin xyz="-0.00552250463639424 2.1693908731044986e-07 -4.169788832414367e-07" rpy="0 0 0"/>
    <mass value="0.1235708646349694"/>
    <inertia ixx="3.3e-05" iyy="1.8e-05" izz="1.8e-05" ixy="-0.0" iyz="-0.0" ixz="-0.0"/>
  </inertial>
  <visual>
    <origin xyz="0.101741 -0.006255 -0.013032" rpy="0 0 0"/>
    <geometry>
      <mesh filename="file://$(find leremix_description)/meshes/back_wheel_mount_1.stl" scale="0.001 0.001 0.001"/>
    </geometry>
    <material name="silver"/>
  </visual>
  <collision>
    <origin xyz="0.101741 -0.006255 -0.013032" rpy="0 0 0"/>
    <geometry>
      <mesh filename="file://$(find leremix_description)/meshes/back_wheel_mount_1.stl" scale="0.001 0.001 0.001"/>
    </geometry>
  </collision>
</link>

<link name="back_wheel_1">
  <inertial>
    <origin xyz="-0.015374617586046052 1.0825471297073314e-07 -3.3995992976439127e-07" rpy="0 0 0"/>
    <mass value="1.3542854082324305"/>
    <inertia ixx="0.00188" iyy="0.001094" izz="0.001094" ixy="0.0" iyz="0.0" ixz="-0.0"/>
  </inertial>
  <visual>
    <origin xyz="0.108916 -0.006255 -0.013032" rpy="0 0 0"/>
    <geometry>
      <mesh filename="file://$(find leremix_description)/meshes/back_wheel_1.stl" scale="0.001 0.001 0.001"/>
    </geometry>
    <material name="silver"/>
  </visual>
  <collision>
    <origin xyz="0.108916 -0.006255 -0.013032" rpy="0 0 0"/>
    <geometry>
      <mesh filename="file://$(find leremix_description)/meshes/back_wheel_1.stl" scale="0.001 0.001 0.001"/>
    </geometry>
  </collision>
</link>

<link name="left_servo_1">
  <inertial>
    <origin xyz="0.016924848422785556 0.00888142204280122 -0.019716322743522894" rpy="0 0 0"/>
    <mass value="0.27778201352216375"/>
    <inertia ixx="6.8e-05" iyy="6.3e-05" izz="3.8e-05" ixy="-4e-06" iyz="1e-06" ixz="0.0"/>
  </inertial>
  <visual>
    <origin xyz="-0.034669 -0.07585 -0.045832" rpy="0 0 0"/>
    <geometry>
      <mesh filename="file://$(find leremix_description)/meshes/left_servo_1.stl" scale="0.001 0.001 0.001"/>
    </geometry>
    <material name="silver"/>
  </visual>
  <collision>
    <origin xyz="-0.034669 -0.07585 -0.045832" rpy="0 0 0"/>
    <geometry>
      <mesh filename="file://$(find leremix_description)/meshes/left_servo_1.stl" scale="0.001 0.001 0.001"/>
    </geometry>
  </collision>
</link>

<link name="left_wheel_mount_1">
  <inertial>
    <origin xyz="0.002761280694251654 0.004782713545836703 1.954960941463746e-07" rpy="0 0 0"/>
    <mass value="0.1235708646349694"/>
    <inertia ixx="2.2e-05" iyy="2.9e-05" izz="1.8e-05" ixy="6e-06" iyz="0.0" ixz="-0.0"/>
  </inertial>
  <visual>
    <origin xyz="-0.060298 -0.099852 -0.013014" rpy="0 0 0"/>
    <geometry>
      <mesh filename="file://$(find leremix_description)/meshes/left_wheel_mount_1.stl" scale="0.001 0.001 0.001"/>
    </geometry>
    <material name="silver"/>
  </visual>
  <collision>
    <origin xyz="-0.060298 -0.099852 -0.013014" rpy="0 0 0"/>
    <geometry>
      <mesh filename="file://$(find leremix_description)/meshes/left_wheel_mount_1.stl" scale="0.001 0.001 0.001"/>
    </geometry>
  </collision>
</link>

<link name="left_wheel_1">
  <inertial>
    <origin xyz="0.007687902917319828 0.013315587953577235 3.152556867624251e-07" rpy="0 0 0"/>
    <mass value="1.3542854082324305"/>
    <inertia ixx="0.00129" iyy="0.001683" izz="0.001094" ixy="0.00034" iyz="0.0" ixz="-0.0"/>
  </inertial>
  <visual>
    <origin xyz="-0.063885 -0.106065 -0.013014" rpy="0 0 0"/>
    <geometry>
      <mesh filename="file://$(find leremix_description)/meshes/left_wheel_1.stl" scale="0.001 0.001 0.001"/>
    </geometry>
    <material name="silver"/>
  </visual>
  <collision>
    <origin xyz="-0.063885 -0.106065 -0.013014" rpy="0 0 0"/>
    <geometry>
      <mesh filename="file://$(find leremix_description)/meshes/left_wheel_1.stl" scale="0.001 0.001 0.001"/>
    </geometry>
  </collision>
</link>

<link name="orin_1">
  <inertial>
    <origin xyz="-0.029980953546155695 0.046403399993093494 0.010404046498042052" rpy="0 0 0"/>
    <mass value="0.4488469641841115"/>
    <inertia ixx="0.000252" iyy="0.000254" izz="0.000445" ixy="-1e-05" iyz="-3e-06" ixz="-3e-05"/>
  </inertial>
  <visual>
    <origin xyz="0.015686 0.039888 -0.067333" rpy="0 0 0"/>
    <geometry>
      <mesh filename="file://$(find leremix_description)/meshes/orin_1.stl" scale="0.001 0.001 0.001"/>
    </geometry>
    <material name="silver"/>
  </visual>
  <collision>
    <origin xyz="0.015686 0.039888 -0.067333" rpy="0 0 0"/>
    <geometry>
      <mesh filename="file://$(find leremix_description)/meshes/orin_1.stl" scale="0.001 0.001 0.001"/>
    </geometry>
  </collision>
</link>

<link name="orin_mount_1">
  <inertial>
    <origin xyz="0.04638649432312704 0.03968504649542948 0.001670301967852575" rpy="0 0 0"/>
    <mass value="0.0924663763130813"/>
    <inertia ixx="0.00014" iyy="8.1e-05" izz="0.000221" ixy="1e-06" iyz="-0.0" ixz="-0.0"/>
  </inertial>
  <visual>
    <origin xyz="0.093686 0.033751 -0.055333" rpy="0 0 0"/>
    <geometry>
      <mesh filename="file://$(find leremix_description)/meshes/orin_mount_1.stl" scale="0.001 0.001 0.001"/>
    </geometry>
    <material name="silver"/>
  </visual>
  <collision>
    <origin xyz="0.093686 0.033751 -0.055333" rpy="0 0 0"/>
    <geometry>
      <mesh filename="file://$(find leremix_description)/meshes/orin_mount_1.stl" scale="0.001 0.001 0.001"/>
    </geometry>
  </collision>
</link>

<link name="usb_pd_mount_1">
  <inertial>
    <origin xyz="0.010000012770315852 0.0004321362500251903 0.0019462189817742955" rpy="0 0 0"/>
    <mass value="0.0531436807920926"/>
    <inertia ixx="1.1e-05" iyy="9e-06" izz="2e-05" ixy="0.0" iyz="-0.0" ixz="0.0"/>
  </inertial>
  <visual>
    <origin xyz="-0.026314 -0.006249 -0.002833" rpy="0 0 0"/>
    <geometry>
      <mesh filename="file://$(find leremix_description)/meshes/usb_pd_mount_1.stl" scale="0.001 0.001 0.001"/>
    </geometry>
    <material name="silver"/>
  </visual>
  <collision>
    <origin xyz="-0.026314 -0.006249 -0.002833" rpy="0 0 0"/>
    <geometry>
      <mesh filename="file://$(find leremix_description)/meshes/usb_pd_mount_1.stl" scale="0.001 0.001 0.001"/>
    </geometry>
  </collision>
</link>

<link name="arm_base_1">
  <inertial>
    <origin xyz="-0.03974904687233398 -0.04000260996890506 0.021865722383822" rpy="0 0 0"/>
    <mass value="1.2829039880853146"/>
    <inertia ixx="0.001557" iyy="0.00136" izz="0.001775" ixy="0.0" iyz="0.0" ixz="0.000249"/>
  </inertial>
  <visual>
    <origin xyz="-0.096314 -0.046248 -0.055333" rpy="0 0 0"/>
    <geometry>
      <mesh filename="file://$(find leremix_description)/meshes/arm_base_1.stl" scale="0.001 0.001 0.001"/>
    </geometry>
    <material name="silver"/>
  </visual>
  <collision>
    <origin xyz="-0.096314 -0.046248 -0.055333" rpy="0 0 0"/>
    <geometry>
      <mesh filename="file://$(find leremix_description)/meshes/arm_base_1.stl" scale="0.001 0.001 0.001"/>
    </geometry>
  </collision>
</link>

<link name="imu_1">
  <inertial>
    <origin xyz="0.007620012770360919 -0.010795411240414958 -0.0008831346730460293" rpy="0 0 0"/>
    <mass value="0.007606013634323334"/>
    <inertia ixx="0.0" iyy="0.0" izz="1e-06" ixy="0.0" iyz="-0.0" ixz="0.0"/>
  </inertial>
  <visual>
    <origin xyz="0.001286 -0.016409 -0.061333" rpy="0 0 0"/>
    <geometry>
      <mesh filename="file://$(find leremix_description)/meshes/imu_1.stl" scale="0.001 0.001 0.001"/>
    </geometry>
    <material name="silver"/>
  </visual>
  <collision>
    <origin xyz="0.001286 -0.016409 -0.061333" rpy="0 0 0"/>
    <geometry>
      <mesh filename="file://$(find leremix_description)/meshes/imu_1.stl" scale="0.001 0.001 0.001"/>
    </geometry>
  </collision>
</link>

<link name="imu_mount_1">
  <inertial>
    <origin xyz="1.2770350805470232e-08 -0.020000411240417185 0.001123021969500565" rpy="0 0 0"/>
    <mass value="0.011661793388699252"/>
    <inertia ixx="1e-06" iyy="0.0" izz="2e-06" ixy="0.0" iyz="-0.0" ixz="0.0"/>
  </inertial>
  <visual>
    <origin xyz="-0.006314 -0.026249 -0.055333" rpy="0 0 0"/>
    <geometry>
      <mesh filename="file://$(find leremix_description)/meshes/imu_mount_1.stl" scale="0.001 0.001 0.001"/>
    </geometry>
    <material name="silver"/>
  </visual>
  <collision>
    <origin xyz="-0.006314 -0.026249 -0.055333" rpy="0 0 0"/>
    <geometry>
      <mesh filename="file://$(find leremix_description)/meshes/imu_mount_1.stl" scale="0.001 0.001 0.001"/>
    </geometry>
  </collision>
</link>

<link name="hex_1__1__1">
  <inertial>
    <origin xyz="1.2770340021561744e-08 -4.1124072897025243e-07 0.022750198660284805" rpy="0 0 0"/>
    <mass value="0.010098885204413197"/>
    <inertia ixx="2e-06" iyy="2e-06" izz="0.0" ixy="0.0" iyz="0.0" ixz="0.0"/>
  </inertial>
  <visual>
    <origin xyz="0.093686 0.073751 -0.055333" rpy="0 0 0"/>
    <geometry>
      <mesh filename="file://$(find leremix_description)/meshes/hex_1__1__1.stl" scale="0.001 0.001 0.001"/>
    </geometry>
    <material name="silver"/>
  </visual>
  <collision>
    <origin xyz="0.093686 0.073751 -0.055333" rpy="0 0 0"/>
    <geometry>
      <mesh filename="file://$(find leremix_description)/meshes/hex_1__1__1.stl" scale="0.001 0.001 0.001"/>
    </geometry>
  </collision>
</link>

<link name="just_the_tower_v1_1">
  <inertial>
    <origin xyz="-0.04049606823112598 -0.03956398702745904 0.08467203773675318" rpy="0 0 0"/>
    <mass value="1.0410314460711032"/>
    <inertia ixx="0.004373" iyy="0.004248" izz="0.00092" ixy="1e-06" iyz="-2.3e-05" ixz="0.000197"/>
  </inertial>
  <visual>
    <origin xyz="0.033686 -0.046249 -0.105833" rpy="0 0 0"/>
    <geometry>
      <mesh filename="file://$(find leremix_description)/meshes/just_the_tower_v1_1.stl" scale="0.001 0.001 0.001"/>
    </geometry>
    <material name="silver"/>
  </visual>
  <collision>
    <origin xyz="0.033686 -0.046249 -0.105833" rpy="0 0 0"/>
    <geometry>
      <mesh filename="file://$(find leremix_description)/meshes/just_the_tower_v1_1.stl" scale="0.001 0.001 0.001"/>
    </geometry>
  </collision>
</link>

<link name="support_v1_1">
  <inertial>
    <origin xyz="0.014635981127573666 -0.03234967068401176 0.024780476400070195" rpy="0 0 0"/>
    <mass value="0.27772651196367043"/>
    <inertia ixx="0.000201" iyy="0.00017" izz="0.000112" ixy="0.0" iyz="-0.0" ixz="2.1e-05"/>
  </inertial>
  <visual>
    <origin xyz="0.098686 -0.039606 -0.278398" rpy="0 0 0"/>
    <geometry>
      <mesh filename="file://$(find leremix_description)/meshes/support_v1_1.stl" scale="0.001 0.001 0.001"/>
    </geometry>
    <material name="silver"/>
  </visual>
  <collision>
    <origin xyz="0.098686 -0.039606 -0.278398" rpy="0 0 0"/>
    <geometry>
      <mesh filename="file://$(find leremix_description)/meshes/support_v1_1.stl" scale="0.001 0.001 0.001"/>
    </geometry>
  </collision>
</link>

<link name="head_camera_1">
  <inertial>
    <origin xyz="0.012410290676114655 -0.021387219753696996 -0.001003855001055265" rpy="0 0 0"/>
    <mass value="0.35928853728306875"/>
    <inertia ixx="0.000217" iyy="3.3e-05" izz="0.000219" ixy="3e-06" iyz="-0.0" ixz="0.0"/>
  </inertial>
  <visual>
    <origin xyz="0.008147 -0.030006 -0.410381" rpy="0 0 0"/>
    <geometry>
      <mesh filename="file://$(find leremix_description)/meshes/head_camera_1.stl" scale="0.001 0.001 0.001"/>
    </geometry>
    <material name="silver"/>
  </visual>
  <collision>
    <origin xyz="0.008147 -0.030006 -0.410381" rpy="0 0 0"/>
    <geometry>
      <mesh filename="file://$(find leremix_description)/meshes/head_camera_1.stl" scale="0.001 0.001 0.001"/>
    </geometry>
  </collision>
</link>

<link name="hex_1_1">
  <inertial>
    <origin xyz="1.2770345274304429e-08 -4.112407313849875e-07 0.022750198660284972" rpy="0 0 0"/>
    <mass value="0.010098885204413197"/>
    <inertia ixx="2e-06" iyy="2e-06" izz="0.0" ixy="0.0" iyz="0.0" ixz="0.0"/>
  </inertial>
  <visual>
    <origin xyz="0.033686 0.093751 -0.055333" rpy="0 0 0"/>
    <geometry>
      <mesh filename="file://$(find leremix_description)/meshes/hex_1_1.stl" scale="0.001 0.001 0.001"/>
    </geometry>
    <material name="silver"/>
  </visual>
  <collision>
    <origin xyz="0.033686 0.093751 -0.055333" rpy="0 0 0"/>
    <geometry>
      <mesh filename="file://$(find leremix_description)/meshes/hex_1_1.stl" scale="0.001 0.001 0.001"/>
    </geometry>
  </collision>
</link>

<link name="hex_2_1">
  <inertial>
    <origin xyz="1.27703448510319e-08 -4.112407239881266e-07 0.02275019866028697" rpy="0 0 0"/>
    <mass value="0.010098885204413197"/>
    <inertia ixx="2e-06" iyy="2e-06" izz="0.0" ixy="0.0" iyz="0.0" ixz="0.0"/>
  </inertial>
  <visual>
    <origin xyz="0.033686 -0.106249 -0.055333" rpy="0 0 0"/>
    <geometry>
      <mesh filename="file://$(find leremix_description)/meshes/hex_2_1.stl" scale="0.001 0.001 0.001"/>
    </geometry>
    <material name="silver"/>
  </visual>
  <collision>
    <origin xyz="0.033686 -0.106249 -0.055333" rpy="0 0 0"/>
    <geometry>
      <mesh filename="file://$(find leremix_description)/meshes/hex_2_1.stl" scale="0.001 0.001 0.001"/>
    </geometry>
  </collision>
</link>

<link name="hex_1__1___1__1">
  <inertial>
    <origin xyz="1.27703448510319e-08 -4.1124072897025243e-07 0.022750198660286235" rpy="0 0 0"/>
    <mass value="0.010098885204413197"/>
    <inertia ixx="2e-06" iyy="2e-06" izz="0.0" ixy="0.0" iyz="0.0" ixz="0.0"/>
  </inertial>
  <visual>
    <origin xyz="0.093686 -0.086249 -0.055333" rpy="0 0 0"/>
    <geometry>
      <mesh filename="file://$(find leremix_description)/meshes/hex_1__1___1__1.stl" scale="0.001 0.001 0.001"/>
    </geometry>
    <material name="silver"/>
  </visual>
  <collision>
    <origin xyz="0.093686 -0.086249 -0.055333" rpy="0 0 0"/>
    <geometry>
      <mesh filename="file://$(find leremix_description)/meshes/hex_1__1___1__1.stl" scale="0.001 0.001 0.001"/>
    </geometry>
  </collision>
</link>

<link name="last_floor_v1_1">
  <inertial>
    <origin xyz="0.04424084481725389 0.07999958875955743 0.0025001986602848636" rpy="0 0 0"/>
    <mass value="0.7574741481613873"/>
    <inertia ixx="0.00284" iyy="0.000555" izz="0.003391" ixy="-0.0" iyz="0.0" ixz="0.0"/>
  </inertial>
  <visual>
    <origin xyz="0.093686 0.073751 -0.100833" rpy="0 0 0"/>
    <geometry>
      <mesh filename="file://$(find leremix_description)/meshes/last_floor_v1_1.stl" scale="0.001 0.001 0.001"/>
    </geometry>
    <material name="silver"/>
  </visual>
  <collision>
    <origin xyz="0.093686 0.073751 -0.100833" rpy="0 0 0"/>
    <geometry>
      <mesh filename="file://$(find leremix_description)/meshes/last_floor_v1_1.stl" scale="0.001 0.001 0.001"/>
    </geometry>
  </collision>
</link>

<link name="hex_3_1">
  <inertial>
    <origin xyz="1.2770343990609057e-08 -4.1124073166254327e-07 0.023750198660287176" rpy="0 0 0"/>
    <mass value="0.010542792246365427"/>
    <inertia ixx="2e-06" iyy="2e-06" izz="0.0" ixy="0.0" iyz="0.0" ixz="0.0"/>
  </inertial>
  <visual>
    <origin xyz="0.053686 -0.106249 -0.002833" rpy="0 0 0"/>
    <geometry>
      <mesh filename="file://$(find leremix_description)/meshes/hex_3_1.stl" scale="0.001 0.001 0.001"/>
    </geometry>
    <material name="silver"/>
  </visual>
  <collision>
    <origin xyz="0.053686 -0.106249 -0.002833" rpy="0 0 0"/>
    <geometry>
      <mesh filename="file://$(find leremix_description)/meshes/hex_3_1.stl" scale="0.001 0.001 0.001"/>
    </geometry>
  </collision>
</link>

<link name="hex_4_1">
  <inertial>
    <origin xyz="1.2770337808054588e-08 -4.112407171741328e-07 0.023750198660287002" rpy="0 0 0"/>
    <mass value="0.010542792246365427"/>
    <inertia ixx="2e-06" iyy="2e-06" izz="0.0" ixy="0.0" iyz="0.0" ixz="0.0"/>
  </inertial>
  <visual>
    <origin xyz="0.053686 0.093751 -0.002833" rpy="0 0 0"/>
    <geometry>
      <mesh filename="file://$(find leremix_description)/meshes/hex_4_1.stl" scale="0.001 0.001 0.001"/>
    </geometry>
    <material name="silver"/>
  </visual>
  <collision>
    <origin xyz="0.053686 0.093751 -0.002833" rpy="0 0 0"/>
    <geometry>
      <mesh filename="file://$(find leremix_description)/meshes/hex_4_1.stl" scale="0.001 0.001 0.001"/>
    </geometry>
  </collision>
</link>

<link name="upper_floor_1">
  <inertial>
    <origin xyz="0.053943051105274115 -0.09996937953334568 0.00250019866028673" rpy="0 0 0"/>
    <mass value="1.5373763767670563"/>
    <inertia ixx="0.005253" iyy="0.005051" izz="0.010298" ixy="-3e-06" iyz="0.0" ixz="0.0"/>
  </inertial>
  <visual>
    <origin xyz="0.053686 -0.106249 -0.050333" rpy="0 0 0"/>
    <geometry>
      <mesh filename="file://$(find leremix_description)/meshes/upper_floor_1.stl" scale="0.001 0.001 0.001"/>
    </geometry>
    <material name="silver"/>
  </visual>
  <collision>
    <origin xyz="0.053686 -0.106249 -0.050333" rpy="0 0 0"/>
    <geometry>
      <mesh filename="file://$(find leremix_description)/meshes/upper_floor_1.stl" scale="0.001 0.001 0.001"/>
    </geometry>
  </collision>
</link>

<link name="pan_link_1">
  <inertial>
    <origin xyz="0.031555879196698076 -0.0002711567368732038 -0.008540259760939528" rpy="0 0 0"/>
    <mass value="0.5385469320676795"/>
    <inertia ixx="0.000341" iyy="0.000375" izz="0.000154" ixy="-1e-06" iyz="3e-06" ixz="-3.6e-05"/>
  </inertial>
  <visual>
    <origin xyz="0.052786 -0.007506 -0.331739" rpy="0 0 0"/>
    <geometry>
      <mesh filename="file://$(find leremix_description)/meshes/pan_link_1.stl" scale="0.001 0.001 0.001"/>
    </geometry>
    <material name="silver"/>
  </visual>
  <collision>
    <origin xyz="0.052786 -0.007506 -0.331739" rpy="0 0 0"/>
    <geometry>
      <mesh filename="file://$(find leremix_description)/meshes/pan_link_1.stl" scale="0.001 0.001 0.001"/>
    </geometry>
  </collision>
</link>

<link name="tilt_servo_1">
  <inertial>
    <origin xyz="-0.010249987236395799 -0.01602665209561295 0.019999217452207174" rpy="0 0 0"/>
    <mass value="0.2843033831904074"/>
    <inertia ixx="7.3e-05" iyy="6.2e-05" izz="4e-05" ixy="0.0" iyz="1e-06" ixz="-0.0"/>
  </inertial>
  <visual>
    <origin xyz="0.011936 -0.023806 -0.352139" rpy="0 0 0"/>
    <geometry>
      <mesh filename="file://$(find leremix_description)/meshes/tilt_servo_1.stl" scale="0.001 0.001 0.001"/>
    </geometry>
    <material name="silver"/>
  </visual>
  <collision>
    <origin xyz="0.011936 -0.023806 -0.352139" rpy="0 0 0"/>
    <geometry>
      <mesh filename="file://$(find leremix_description)/meshes/tilt_servo_1.stl" scale="0.001 0.001 0.001"/>
    </geometry>
  </collision>
</link>

<link name="tilt_link_cover_1">
  <inertial>
    <origin xyz="0.011005781542116733 -0.015349793935527876 0.0011419800510757971" rpy="0 0 0"/>
    <mass value="0.10853073755546007"/>
    <inertia ixx="4.6e-05" iyy="2.7e-05" izz="5.8e-05" ixy="-0.0" iyz="-0.0" ixz="-0.0"/>
  </inertial>
  <visual>
    <origin xyz="0.032436 -0.023806 -0.352139" rpy="0 0 0"/>
    <geometry>
      <mesh filename="file://$(find leremix_description)/meshes/tilt_link_cover_1.stl" scale="0.001 0.001 0.001"/>
    </geometry>
    <material name="silver"/>
  </visual>
  <collision>
    <origin xyz="0.032436 -0.023806 -0.352139" rpy="0 0 0"/>
    <geometry>
      <mesh filename="file://$(find leremix_description)/meshes/tilt_link_cover_1.stl" scale="0.001 0.001 0.001"/>
    </geometry>
  </collision>
</link>

<link name="realsense_support_v1_1">
  <inertial>
    <origin xyz="0.0283526934878841 0.38463234994364043 0.049048394161129105" rpy="0 0 0"/>
    <mass value="0.22381597612221305"/>
    <inertia ixx="0.000144" iyy="4.8e-05" izz="0.000121" ixy="0.0" iyz="0.0" ixz="-5e-06"/>
  </inertial>
  <visual>
    <origin xyz="0.048392 0.377033 -0.350253" rpy="0 0 0"/>
    <geometry>
      <mesh filename="file://$(find leremix_description)/meshes/realsense_support_v1_1.stl" scale="0.001 0.001 0.001"/>
    </geometry>
    <material name="silver"/>
  </visual>
  <collision>
    <origin xyz="0.048392 0.377033 -0.350253" rpy="0 0 0"/>
    <geometry>
      <mesh filename="file://$(find leremix_description)/meshes/realsense_support_v1_1.stl" scale="0.001 0.001 0.001"/>
    </geometry>
  </collision>
</link>

<link name="pan_servo__1__1">
  <inertial>
    <origin xyz="0.01619904033356738 -0.010249587164135897 -0.015772745186285686" rpy="0 0 0"/>
    <mass value="0.2843033831904074"/>
    <inertia ixx="4e-05" iyy="7.3e-05" izz="6.2e-05" ixy="0.0" iyz="0.0" ixz="-1e-06"/>
  </inertial>
  <visual>
    <origin xyz="0.081786 -0.017756 -0.328939" rpy="0 0 0"/>
    <geometry>
      <mesh filename="file://$(find leremix_description)/meshes/pan_servo__1__1.stl" scale="0.001 0.001 0.001"/>
    </geometry>
    <material name="silver"/>
  </visual>
  <collision>
    <origin xyz="0.081786 -0.017756 -0.328939" rpy="0 0 0"/>
    <geometry>
      <mesh filename="file://$(find leremix_description)/meshes/pan_servo__1__1.stl" scale="0.001 0.001 0.001"/>
    </geometry>
  </collision>
</link>

<link name="wrist_camera_mod_v1_1">
  <inertial>
    <origin xyz="0.03555058372335673 0.01486419658871679 0.020139907648103472" rpy="0 0 0"/>
    <mass value="0.16746945951855144"/>
    <inertia ixx="0.000137" iyy="0.000128" izz="0.000102" ixy="-3.2e-05" iyz="-5.2e-05" ixz="-4.9e-05"/>
  </inertial>
  <visual>
    <origin xyz="-0.148732 0.023478 -0.144033" rpy="0 0 0"/>
    <geometry>
      <mesh filename="file://$(find leremix_description)/meshes/wrist_camera_mod_v1_1.stl" scale="0.001 0.001 0.001"/>
    </geometry>
    <material name="silver"/>
  </visual>
  <collision>
    <origin xyz="-0.148732 0.023478 -0.144033" rpy="0 0 0"/>
    <geometry>
      <mesh filename="file://$(find leremix_description)/meshes/wrist_camera_mod_v1_1.stl" scale="0.001 0.001 0.001"/>
    </geometry>
  </collision>
</link>

<link name="wrist_camera_v1_1">
  <inertial>
    <origin xyz="0.011412389966657083 -0.012583940898416532 0.0006875527947957649" rpy="0 0 0"/>
    <mass value="0.016638125458728874"/>
    <inertia ixx="1e-06" iyy="1e-06" izz="2e-06" ixy="0.0" iyz="-0.0" ixz="-0.0"/>
  </inertial>
  <visual>
    <origin xyz="-0.203344 -0.022435 -0.206178" rpy="0 0 0"/>
    <geometry>
      <mesh filename="file://$(find leremix_description)/meshes/wrist_camera_v1_1.stl" scale="0.001 0.001 0.001"/>
    </geometry>
    <material name="silver"/>
  </visual>
  <collision>
    <origin xyz="-0.203344 -0.022435 -0.206178" rpy="0 0 0"/>
    <geometry>
      <mesh filename="file://$(find leremix_description)/meshes/wrist_camera_v1_1.stl" scale="0.001 0.001 0.001"/>
    </geometry>
  </collision>
</link>

<link name="lidar_1">
  <inertial>
    <origin xyz="0.02158353327371662 -0.021594034021135324 0.01401862909025581" rpy="0 0 0"/>
    <mass value="0.25367500028622497"/>
    <inertia ixx="0.000111" iyy="0.000111" izz="0.000157" ixy="-0.0" iyz="-0.0" ixz="0.0"/>
  </inertial>
  <visual>
    <origin xyz="-0.067139 -0.027748 -0.005833" rpy="0 0 0"/>
    <geometry>
      <mesh filename="file://$(find leremix_description)/meshes/lidar_1.stl" scale="0.001 0.001 0.001"/>
    </geometry>
    <material name="silver"/>
  </visual>
  <collision>
    <origin xyz="-0.067139 -0.027748 -0.005833" rpy="0 0 0"/>
    <geometry>
      <mesh filename="file://$(find leremix_description)/meshes/lidar_1.stl" scale="0.001 0.001 0.001"/>
    </geometry>
  </collision>
</link>

<link name="suport_lidar_v1_1">
  <inertial>
    <origin xyz="0.0010725074889099823 0.039999497257626894 0.002427078788166909" rpy="0 0 0"/>
    <mass value="0.050642865544512895"/>
    <inertia ixx="4.4e-05" iyy="1.8e-05" izz="6.2e-05" ixy="0.0" iyz="-0.0" ixz="-0.0"/>
  </inertial>
  <visual>
    <origin xyz="-0.086314 0.033751 -0.002833" rpy="0 0 0"/>
    <geometry>
      <mesh filename="file://$(find leremix_description)/meshes/suport_lidar_v1_1.stl" scale="0.001 0.001 0.001"/>
    </geometry>
    <material name="silver"/>
  </visual>
  <collision>
    <origin xyz="-0.086314 0.033751 -0.002833" rpy="0 0 0"/>
    <geometry>
      <mesh filename="file://$(find leremix_description)/meshes/suport_lidar_v1_1.stl" scale="0.001 0.001 0.001"/>
    </geometry>
  </collision>
</link>

<joint name="Rigid 44" type="fixed">
  <origin xyz="-0.045652 -0.05025 0.0278" rpy="0 0 0"/>
  <parent link="arm_base_1"/>
  <child link="arm_base_rotation_servo_1"/>
</joint>

<joint name="1" type="continuous">
  <origin xyz="0.0328 0.01025 0.0346" rpy="0 0 0"/>
  <parent link="arm_base_rotation_servo_1"/>
  <child link="arm_base_rotation_link_1"/>
  <axis xyz="0.0 -0.0 -1.0"/>
</joint>

<joint name="Rigid 46" type="fixed">
  <origin xyz="0.04085 -0.023 0.0232" rpy="0 0 0"/>
  <parent link="arm_base_rotation_link_1"/>
  <child link="arm_base_rotation_link_cover_1"/>
</joint>

<joint name="Rigid 48" type="fixed">
  <origin xyz="0.04085 0.0163 0.0194" rpy="0 0 0"/>
  <parent link="arm_base_rotation_link_1"/>
  <child link="arm_shoulder_servo_1"/>
</joint>

<joint name="2" type="continuous">
  <origin xyz="-0.01025 -0.0346 0.0328" rpy="0 0 0"/>
  <parent link="arm_shoulder_servo_1"/>
  <child link="arm_shoulder_link_1"/>
  <axis xyz="-0.0 -1.0 -0.0"/>
</joint>

<joint name="Rigid 50" type="fixed">
  <origin xyz="-0.097591 0.0361 -0.031119" rpy="0 0 0"/>
  <parent link="arm_shoulder_link_1"/>
  <child link="arm_elbow_servo_1"/>
</joint>

<joint name="3" type="continuous">
  <origin xyz="-0.01839 -0.0346 0.02903" rpy="0 0 0"/>
  <parent link="arm_elbow_servo_1"/>
  <child link="arm_elbow_link_1"/>
  <axis xyz="-0.0 -1.0 -0.0"/>
</joint>

<joint name="Rigid 52" type="fixed">
  <origin xyz="0.091598 0.0361 0.04978" rpy="0 0 0"/>
  <parent link="arm_elbow_link_1"/>
  <child link="arm_wrist_tilt_servo_1"/>
</joint>

<joint name="4" type="continuous">
  <origin xyz="0.034335 -0.0346 -0.001411" rpy="0 0 0"/>
  <parent link="arm_wrist_tilt_servo_1"/>
  <child link="arm_wrist_link_1"/>
  <axis xyz="-0.0 -1.0 -0.0"/>
</joint>

<joint name="arm_wrist_roll_solid" type="fixed">
  <origin xyz="0.037689 -0.0089 -0.045645" rpy="0 0 0"/>
  <parent link="arm_wrist_link_1"/>
  <child link="arm_wrist_roll_servo_1"/>
</joint>

<joint name="5" type="continuous">
  <origin xyz="-0.007533 0.029 -0.007495" rpy="0 0 0"/>
  <parent link="arm_wrist_roll_servo_1"/>
  <child link="arm_gripper_1"/>
  <axis xyz="0.493558 0.0 -0.869713"/>
</joint>

<joint name="Rigid 56" type="fixed">
  <origin xyz="0.019676 -0.013798 -0.003637" rpy="0 0 0"/>
  <parent link="arm_gripper_1"/>
  <child link="arm_gripper_servo_1"/>
</joint>

<joint name="6" type="continuous">
  <origin xyz="-0.02354 0.03452 -0.025145" rpy="0 0 0"/>
  <parent link="arm_gripper_servo_1"/>
  <child link="arm_jaw_1"/>
  <axis xyz="-0.868584 0.050948 -0.492917"/>
</joint>

<joint name="Rigid 75" type="fixed">
  <origin xyz="0.028994 -0.073033 0.002833" rpy="0 0 0"/>
  <parent link="base_link"/>
  <child link="right_servo_mount_1"/>
</joint>

<joint name="Rigid 76" type="fixed">
  <origin xyz="0.005665 0.009674 0.0185" rpy="0 0 0"/>
  <parent link="right_servo_mount_1"/>
  <child link="right_servo_1"/>
</joint>

<joint name="wheel2_rotation" type="continuous">
  <origin xyz="0.025689 -0.023967 -0.008282" rpy="0 0 0"/>
  <parent link="right_servo_1"/>
  <child link="right_wheel_mount_1"/>
  <axis xyz="-0.5 0.866025 -0.0"/>
</joint>

<joint name="Rigid 79" type="fixed">
  <origin xyz="-0.093686 -0.013751 0.002833" rpy="0 0 0"/>
  <parent link="base_link"/>
  <child link="back_servo_mount_1"/>
</joint>

<joint name="Rigid 80" type="fixed">
  <origin xyz="0.038994 0.102851 0.002833" rpy="0 0 0"/>
  <parent link="base_link"/>
  <child link="left_servo_mount_1"/>
</joint>

<joint name="Rigid 81" type="fixed">
  <origin xyz="0.025545 0.030256 0.042999" rpy="0 0 0"/>
  <parent link="back_servo_mount_1"/>
  <child link="back_servo_1"/>
</joint>

<joint name="Rigid 82" type="fixed">
  <origin xyz="0.003587 -0.006214 0.0" rpy="0 0 0"/>
  <parent link="right_wheel_mount_1"/>
  <child link="right_wheel_1"/>
</joint>

<joint name="wheel1_rotation" type="continuous">
  <origin xyz="-0.0336 -0.01025 -0.0328" rpy="0 0 0"/>
  <parent link="back_servo_1"/>
  <child link="back_wheel_mount_1"/>
  <axis xyz="-1.0 -0.0 -0.0"/>
</joint>

<joint name="Rigid 85" type="fixed">
  <origin xyz="-0.007175 0.0 0.0" rpy="0 0 0"/>
  <parent link="back_wheel_mount_1"/>
  <child link="back_wheel_1"/>
</joint>

<joint name="Rigid 86" type="fixed">
  <origin xyz="-0.004325 -0.027001 0.042999" rpy="0 0 0"/>
  <parent link="left_servo_mount_1"/>
  <child link="left_servo_1"/>
</joint>

<joint name="wheel3_rotation" type="continuous">
  <origin xyz="0.025629 0.024002 -0.032818" rpy="0 0 0"/>
  <parent link="left_servo_1"/>
  <child link="left_wheel_mount_1"/>
  <axis xyz="-0.5 -0.866025 -0.0"/>
</joint>

<joint name="Rigid 88" type="fixed">
  <origin xyz="0.003587 0.006213 0.0" rpy="0 0 0"/>
  <parent link="left_wheel_mount_1"/>
  <child link="left_wheel_1"/>
</joint>

<joint name="Rigid 90" type="fixed">
  <origin xyz="0.078 -0.006137 0.012" rpy="0 0 0"/>
  <parent link="orin_mount_1"/>
  <child link="orin_1"/>
</joint>

<joint name="Rigid 91" type="fixed">
  <origin xyz="-0.04 -0.14 0.005" rpy="0 0 0"/>
  <parent link="upper_floor_1"/>
  <child link="orin_mount_1"/>
</joint>

<joint name="Rigid 100" type="fixed">
  <origin xyz="0.026314 0.006249 0.002833" rpy="0 0 0"/>
  <parent link="base_link"/>
  <child link="usb_pd_mount_1"/>
</joint>

<joint name="Rigid 103" type="fixed">
  <origin xyz="0.15 -0.060001 0.005" rpy="0 0 0"/>
  <parent link="upper_floor_1"/>
  <child link="arm_base_1"/>
</joint>

<joint name="Rigid 115" type="fixed">
  <origin xyz="-0.0076 -0.00984 0.006" rpy="0 0 0"/>
  <parent link="imu_mount_1"/>
  <child link="imu_1"/>
</joint>

<joint name="Rigid 117" type="fixed">
  <origin xyz="0.06 -0.08 0.005" rpy="0 0 0"/>
  <parent link="upper_floor_1"/>
  <child link="imu_mount_1"/>
</joint>

<joint name="Rigid 147" type="fixed">
  <origin xyz="-0.04 -0.18 0.005" rpy="0 0 0"/>
  <parent link="upper_floor_1"/>
  <child link="hex_1__1__1"/>
</joint>

<joint name="Rigid 156" type="fixed">
  <origin xyz="0.06 0.12 0.005" rpy="0 0 0"/>
  <parent link="last_floor_v1_1"/>
  <child link="just_the_tower_v1_1"/>
</joint>

<joint name="Rigid 157" type="fixed">
  <origin xyz="-0.065 -0.006643 0.172565" rpy="0 0 0"/>
  <parent link="just_the_tower_v1_1"/>
  <child link="support_v1_1"/>
</joint>

<joint name="Rigid 165" type="fixed">
  <origin xyz="0.040245 0.407039 0.060128" rpy="0 0 0"/>
  <parent link="realsense_support_v1_1"/>
  <child link="head_camera_1"/>
</joint>

<joint name="Rigid 166" type="fixed">
  <origin xyz="0.02 -0.2 0.005" rpy="0 0 0"/>
  <parent link="upper_floor_1"/>
  <child link="hex_1_1"/>
</joint>

<joint name="Rigid 167" type="fixed">
  <origin xyz="0.02 0.0 0.005" rpy="0 0 0"/>
  <parent link="upper_floor_1"/>
  <child link="hex_2_1"/>
</joint>

<joint name="Rigid 168" type="fixed">
  <origin xyz="-0.04 -0.02 0.005" rpy="0 0 0"/>
  <parent link="upper_floor_1"/>
  <child link="hex_1__1___1__1"/>
</joint>

<joint name="Rigid 169" type="fixed">
  <origin xyz="0.0 0.0 0.0455" rpy="0 0 0"/>
  <parent link="hex_1__1__1"/>
  <child link="last_floor_v1_1"/>
</joint>

<joint name="Rigid 172" type="fixed">
  <origin xyz="-0.053686 0.106249 0.002833" rpy="0 0 0"/>
  <parent link="base_link"/>
  <child link="hex_3_1"/>
</joint>

<joint name="Rigid 173" type="fixed">
  <origin xyz="-0.053686 -0.093751 0.002833" rpy="0 0 0"/>
  <parent link="base_link"/>
  <child link="hex_4_1"/>
</joint>

<joint name="Rigid 174" type="fixed">
  <origin xyz="0.0 0.0 0.0475" rpy="0 0 0"/>
  <parent link="hex_3_1"/>
  <child link="upper_floor_1"/>
</joint>

<joint name="camera_pan" type="continuous">
  <origin xyz="0.029 -0.01025 0.0028" rpy="0 0 0"/>
  <parent link="pan_servo__1__1"/>
  <child link="pan_link_1"/>
  <axis xyz="0.0 -0.0 -1.0"/>
</joint>

<joint name="Rigid 176" type="fixed">
  <origin xyz="0.04085 0.0163 0.0204" rpy="0 0 0"/>
  <parent link="pan_link_1"/>
  <child link="tilt_servo_1"/>
</joint>

<joint name="Rigid 177" type="fixed">
  <origin xyz="-0.0205 0.0 0.0" rpy="0 0 0"/>
  <parent link="tilt_servo_1"/>
  <child link="tilt_link_cover_1"/>
</joint>

<joint name="camera_tilt" type="continuous">
  <origin xyz="-0.036456 -0.400839 -0.001886" rpy="0 0 0"/>
  <parent link="tilt_servo_1"/>
  <child link="realsense_support_v1_1"/>
  <axis xyz="0.0 1.0 0.0"/>
</joint>

<joint name="Rigid 179" type="fixed">
  <origin xyz="0.0169 -0.02185 0.050541" rpy="0 0 0"/>
  <parent link="support_v1_1"/>
  <child link="pan_servo__1__1"/>
</joint>

<joint name="Rigid 182" type="fixed">
  <origin xyz="-0.005438 -0.034526 -0.01904" rpy="0 0 0"/>
  <parent link="arm_gripper_1"/>
  <child link="wrist_camera_mod_v1_1"/>
</joint>

<joint name="Rigid 183" type="fixed">
  <origin xyz="0.054612 0.045913 0.062145" rpy="0 0 0"/>
  <parent link="wrist_camera_mod_v1_1"/>
  <child link="wrist_camera_v1_1"/>
</joint>

<joint name="Rigid 184" type="fixed">
  <origin xyz="-0.019175 0.061499 0.003" rpy="0 0 0"/>
  <parent link="suport_lidar_v1_1"/>
  <child link="lidar_1"/>
</joint>

<joint name="Rigid 185" type="fixed">
  <origin xyz="0.086314 -0.033751 0.002833" rpy="0 0 0"/>
  <parent link="base_link"/>
  <child link="suport_lidar_v1_1"/>
</joint>

<!-- ros2_control hardware interface
<ros2_control name="leremix_hardware" type="system">
  <hardware>
    <plugin>leremix_control_plugin/Esp32SystemTopic</plugin>
    <param name="base_cmd_topic">/esp32/base_cmd</param>
    <param name="arm_cmd_topic">/esp32/arm_cmd</param>
    <param name="state_topic">/esp32/joint_states</param>
    <param name="publish_if_unchanged">true</param>
  </hardware>
  

  <joint name="back_motor_rotation">
    <command_interface name="velocity"/>
    <state_interface name="position"/>
    <state_interface name="velocity"/>
  </joint>
  <joint name="left_motor_rotation">
    <command_interface name="velocity"/>
    <state_interface name="position"/>
    <state_interface name="velocity"/>
  </joint>
  <joint name="right_motor_rotation">
    <command_interface name="velocity"/>
    <state_interface name="position"/>
    <state_interface name="velocity"/>
  </joint>
  
  <joint name="1">
    <command_interface name="position"/>
    <state_interface name="position"/>
  </joint>
  <joint name="2">
    <command_interface name="position"/>
    <state_interface name="position"/>
  </joint>
  <joint name="3">
    <command_interface name="position"/>
    <state_interface name="position"/>
  </joint>
  <joint name="4">
    <command_interface name="position"/>
    <state_interface name="position"/>
  </joint>
  <joint name="5">
    <command_interface name="position"/>
    <state_interface name="position"/>
  </joint>
  <joint name="6">
    <command_interface name="position"/>
    <state_interface name="position"/>
  </joint>
  <joint name="camera_tilt">
    <command_interface name="position"/>
    <state_interface name="position"/>
  </joint>
</ros2_control>
-->

</robot>