<?xml version="1.0" ?>
<robot name="LeRemix" xmlns:xacro="http://www.ros.org/wiki/xacro">

<xacro:include filename="$(find leremix_description)/urdf/materials.xacro" />

<link name="base_link">
  <inertial>
    <origin xyz="3.340802284881761e-05 0.0062553486303636415 0.0025000000000001423" rpy="0 0 0"/>
    <mass value="1.5793453539076086"/>
    <inertia ixx="0.005179" iyy="0.00541" izz="0.010582" ixy="3e-06" iyz="-0.0" ixz="0.0"/>
  </inertial>
  <visual>
    <origin xyz="0 0 0" rpy="0 0 0"/>
    <geometry>
      <mesh filename="file://$(find leremix_description)/meshes/base_link.stl" scale="0.001 0.001 0.001"/>
    </geometry>
    <material name="silver"/>
  </visual>
  <collision>
    <origin xyz="0 0 0" rpy="0 0 0"/>
    <geometry>
      <mesh filename="file://$(find leremix_description)/meshes/base_link.stl" scale="0.001 0.001 0.001"/>
    </geometry>
  </collision>
</link>

<link name="arm_base_rotation_servo_1">
  <inertial>
    <origin xyz="0.010249751352689343 -0.01999903218942549 0.016027064924724457" rpy="0 0 0"/>
    <mass value="0.2843033831904074"/>
    <inertia ixx="7.3e-05" iyy="4e-05" izz="6.2e-05" ixy="-0.0" iyz="1e-06" ixz="0.0"/>
  </inertial>
  <visual>
    <origin xyz="0.01025 0.044348 -0.0853" rpy="0 0 0"/>
    <geometry>
      <mesh filename="file://$(find leremix_description)/meshes/arm_base_rotation_servo_1.stl" scale="0.001 0.001 0.001"/>
    </geometry>
    <material name="silver"/>
  </visual>
  <collision>
    <origin xyz="0.01025 0.044348 -0.0853" rpy="0 0 0"/>
    <geometry>
      <mesh filename="file://$(find leremix_description)/meshes/arm_base_rotation_servo_1.stl" scale="0.001 0.001 0.001"/>
    </geometry>
  </collision>
</link>

<link name="arm_base_rotation_link_1">
  <inertial>
    <origin xyz="-0.0002718182200486687 -0.03155587105255636 -0.00954044964992927" rpy="0 0 0"/>
    <mass value="0.5385469320676795"/>
    <inertia ixx="0.000375" iyy="0.000341" izz="0.000154" ixy="1e-06" iyz="3.6e-05" ixz="3e-06"/>
  </inertial>
  <visual>
    <origin xyz="0.0 0.077148 -0.1199" rpy="0 0 0"/>
    <geometry>
      <mesh filename="file://$(find leremix_description)/meshes/arm_base_rotation_link_1.stl" scale="0.001 0.001 0.001"/>
    </geometry>
    <material name="silver"/>
  </visual>
  <collision>
    <origin xyz="0.0 0.077148 -0.1199" rpy="0 0 0"/>
    <geometry>
      <mesh filename="file://$(find leremix_description)/meshes/arm_base_rotation_link_1.stl" scale="0.001 0.001 0.001"/>
    </geometry>
  </collision>
</link>

<link name="arm_base_rotation_link_cover_1">
  <inertial>
    <origin xyz="0.02324954458129752 0.00949422660202355 -0.0026582098379117625" rpy="0 0 0"/>
    <mass value="0.10853073755546007"/>
    <inertia ixx="2.7e-05" iyy="4.6e-05" izz="5.8e-05" ixy="0.0" iyz="0.0" ixz="-0.0"/>
  </inertial>
  <visual>
    <origin xyz="0.023 0.117998 -0.1431" rpy="0 0 0"/>
    <geometry>
      <mesh filename="file://$(find leremix_description)/meshes/arm_base_rotation_link_cover_1.stl" scale="0.001 0.001 0.001"/>
    </geometry>
    <material name="silver"/>
  </visual>
  <collision>
    <origin xyz="0.023 0.117998 -0.1431" rpy="0 0 0"/>
    <geometry>
      <mesh filename="file://$(find leremix_description)/meshes/arm_base_rotation_link_cover_1.stl" scale="0.001 0.001 0.001"/>
    </geometry>
  </collision>
</link>

<link name="arm_shoulder_servo_1">
  <inertial>
    <origin xyz="-0.016027313578788078 0.010249995380535046 0.019999027563219196" rpy="0 0 0"/>
    <mass value="0.2843033831904074"/>
    <inertia ixx="6.2e-05" iyy="7.3e-05" izz="4e-05" ixy="-0.0" iyz="0.0" ixz="1e-06"/>
  </inertial>
  <visual>
    <origin xyz="-0.0163 0.117998 -0.1393" rpy="0 0 0"/>
    <geometry>
      <mesh filename="file://$(find leremix_description)/meshes/arm_shoulder_servo_1.stl" scale="0.001 0.001 0.001"/>
    </geometry>
    <material name="silver"/>
  </visual>
  <collision>
    <origin xyz="-0.0163 0.117998 -0.1393" rpy="0 0 0"/>
    <geometry>
      <mesh filename="file://$(find leremix_description)/meshes/arm_shoulder_servo_1.stl" scale="0.001 0.001 0.001"/>
    </geometry>
  </collision>
</link>

<link name="arm_shoulder_link_1">
  <inertial>
    <origin xyz="0.019699275433964603 0.055943201517018516 -0.015368254886744204" rpy="0 0 0"/>
    <mass value="0.9906249126045027"/>
    <inertia ixx="0.001251" iyy="0.000563" izz="0.001549" ixy="8e-06" iyz="0.000304" ixz="-3e-06"/>
  </inertial>
  <visual>
    <origin xyz="0.0183 0.107748 -0.1721" rpy="0 0 0"/>
    <geometry>
      <mesh filename="file://$(find leremix_description)/meshes/arm_shoulder_link_1.stl" scale="0.001 0.001 0.001"/>
    </geometry>
    <material name="silver"/>
  </visual>
  <collision>
    <origin xyz="0.0183 0.107748 -0.1721" rpy="0 0 0"/>
    <geometry>
      <mesh filename="file://$(find leremix_description)/meshes/arm_shoulder_link_1.stl" scale="0.001 0.001 0.001"/>
    </geometry>
  </collision>
</link>

<link name="arm_elbow_servo_1">
  <inertial>
    <origin xyz="-0.016027313578784258 0.015077042423429984 0.016664878981845155" rpy="0 0 0"/>
    <mass value="0.2843033831904074"/>
    <inertia ixx="6.2e-05" iyy="7.1e-05" izz="4.2e-05" ixy="0.0" iyz="-8e-06" ixz="1e-06"/>
  </inertial>
  <visual>
    <origin xyz="-0.0178 0.010157 -0.140981" rpy="0 0 0"/>
    <geometry>
      <mesh filename="file://$(find leremix_description)/meshes/arm_elbow_servo_1.stl" scale="0.001 0.001 0.001"/>
    </geometry>
    <material name="silver"/>
  </visual>
  <collision>
    <origin xyz="-0.0178 0.010157 -0.140981" rpy="0 0 0"/>
    <geometry>
      <mesh filename="file://$(find leremix_description)/meshes/arm_elbow_servo_1.stl" scale="0.001 0.001 0.001"/>
    </geometry>
  </collision>
</link>

<link name="arm_elbow_link_1">
  <inertial>
    <origin xyz="0.015214630153977244 -0.05832612231118732 0.021376936225360188" rpy="0 0 0"/>
    <mass value="0.8772447501056027"/>
    <inertia ixx="0.000993" iyy="0.000473" izz="0.001135" ixy="0.000109" iyz="0.000289" ixz="-4.1e-05"/>
  </inertial>
  <visual>
    <origin xyz="0.0168 -0.008233 -0.170011" rpy="0 0 0"/>
    <geometry>
      <mesh filename="file://$(find leremix_description)/meshes/arm_elbow_link_1.stl" scale="0.001 0.001 0.001"/>
    </geometry>
    <material name="silver"/>
  </visual>
  <collision>
    <origin xyz="0.0168 -0.008233 -0.170011" rpy="0 0 0"/>
    <geometry>
      <mesh filename="file://$(find leremix_description)/meshes/arm_elbow_link_1.stl" scale="0.001 0.001 0.001"/>
    </geometry>
  </collision>
</link>

<link name="arm_wrist_tilt_servo_1">
  <inertial>
    <origin xyz="-0.016027313578783595 -0.021970218393585247 -0.004724477251611736" rpy="0 0 0"/>
    <mass value="0.2843033831904074"/>
    <inertia ixx="6.2e-05" iyy="4.2e-05" izz="7.1e-05" ixy="-1e-06" iyz="8e-06" ixz="0.0"/>
  </inertial>
  <visual>
    <origin xyz="-0.0193 0.083365 -0.219791" rpy="0 0 0"/>
    <geometry>
      <mesh filename="file://$(find leremix_description)/meshes/arm_wrist_tilt_servo_1.stl" scale="0.001 0.001 0.001"/>
    </geometry>
    <material name="silver"/>
  </visual>
  <collision>
    <origin xyz="-0.0193 0.083365 -0.219791" rpy="0 0 0"/>
    <geometry>
      <mesh filename="file://$(find leremix_description)/meshes/arm_wrist_tilt_servo_1.stl" scale="0.001 0.001 0.001"/>
    </geometry>
  </collision>
</link>

<link name="arm_wrist_link_1">
  <inertial>
    <origin xyz="0.016809532618010315 -0.025935209469899856 -0.0048241515605357554" rpy="0 0 0"/>
    <mass value="0.2392168278135931"/>
    <inertia ixx="0.000115" iyy="0.000129" izz="0.000197" ixy="-7e-06" iyz="-1.3e-05" ixz="-1e-06"/>
  </inertial>
  <visual>
    <origin xyz="0.0153 0.1177 -0.21838" rpy="0 0 0"/>
    <geometry>
      <mesh filename="file://$(find leremix_description)/meshes/arm_wrist_link_1.stl" scale="0.001 0.001 0.001"/>
    </geometry>
    <material name="silver"/>
  </visual>
  <collision>
    <origin xyz="0.0153 0.1177 -0.21838" rpy="0 0 0"/>
    <geometry>
      <mesh filename="file://$(find leremix_description)/meshes/arm_wrist_link_1.stl" scale="0.001 0.001 0.001"/>
    </geometry>
  </collision>
</link>

<link name="arm_wrist_roll_servo_1">
  <inertial>
    <origin xyz="0.015998056213156815 0.017108254314661786 -0.00727437724496513" rpy="0 0 0"/>
    <mass value="0.2799142523131049"/>
    <inertia ixx="3.8e-05" iyy="6.1e-05" izz="7.1e-05" ixy="1e-06" iyz="-2e-06" ixz="0.0"/>
  </inertial>
  <visual>
    <origin xyz="0.0242 0.176892 -0.217911" rpy="0 0 0"/>
    <geometry>
      <mesh filename="file://$(find leremix_description)/meshes/arm_wrist_roll_servo_1.stl" scale="0.001 0.001 0.001"/>
    </geometry>
    <material name="silver"/>
  </visual>
  <collision>
    <origin xyz="0.0242 0.176892 -0.217911" rpy="0 0 0"/>
    <geometry>
      <mesh filename="file://$(find leremix_description)/meshes/arm_wrist_roll_servo_1.stl" scale="0.001 0.001 0.001"/>
    </geometry>
  </collision>
</link>

<link name="arm_gripper_1">
  <inertial>
    <origin xyz="0.012976471440619062 -0.027985575300278148 -0.009850406095537195" rpy="0 0 0"/>
    <mass value="0.44698022927880193"/>
    <inertia ixx="0.000308" iyy="0.000179" izz="0.000313" ixy="4.8e-05" iyz="-4.9e-05" ixz="2.3e-05"/>
  </inertial>
  <visual>
    <origin xyz="-0.0048 0.177791 -0.207323" rpy="0 0 0"/>
    <geometry>
      <mesh filename="file://$(find leremix_description)/meshes/arm_gripper_1.stl" scale="0.001 0.001 0.001"/>
    </geometry>
    <material name="silver"/>
  </visual>
  <collision>
    <origin xyz="-0.0048 0.177791 -0.207323" rpy="0 0 0"/>
    <geometry>
      <mesh filename="file://$(find leremix_description)/meshes/arm_gripper_1.stl" scale="0.001 0.001 0.001"/>
    </geometry>
  </collision>
</link>

<link name="arm_gripper_servo_1">
  <inertial>
    <origin xyz="-0.012507811253028377 -0.014128197579570095 0.020144958135724172" rpy="0 0 0"/>
    <mass value="0.2843033831904074"/>
    <inertia ixx="4.3e-05" iyy="7.3e-05" izz="5.9e-05" ixy="-1e-06" iyz="3e-06" ixz="8e-06"/>
  </inertial>
  <visual>
    <origin xyz="-0.010832 0.186887 -0.185606" rpy="0 0 0"/>
    <geometry>
      <mesh filename="file://$(find leremix_description)/meshes/arm_gripper_servo_1.stl" scale="0.001 0.001 0.001"/>
    </geometry>
    <material name="silver"/>
  </visual>
  <collision>
    <origin xyz="-0.010832 0.186887 -0.185606" rpy="0 0 0"/>
    <geometry>
      <mesh filename="file://$(find leremix_description)/meshes/arm_gripper_servo_1.stl" scale="0.001 0.001 0.001"/>
    </geometry>
  </collision>
</link>

<link name="arm_jaw_1">
  <inertial>
    <origin xyz="-0.005398366006794445 -0.026165090582212835 -0.0253929839303193" rpy="0 0 0"/>
    <mass value="0.1586808414280307"/>
    <inertia ixx="8.4e-05" iyy="2.6e-05" izz="7.1e-05" ixy="7e-06" iyz="-1e-05" ixz="-4e-06"/>
  </inertial>
  <visual>
    <origin xyz="0.006557 0.205 -0.22741" rpy="0 0 0"/>
    <geometry>
      <mesh filename="file://$(find leremix_description)/meshes/arm_jaw_1.stl" scale="0.001 0.001 0.001"/>
    </geometry>
    <material name="silver"/>
  </visual>
  <collision>
    <origin xyz="0.006557 0.205 -0.22741" rpy="0 0 0"/>
    <geometry>
      <mesh filename="file://$(find leremix_description)/meshes/arm_jaw_1.stl" scale="0.001 0.001 0.001"/>
    </geometry>
  </collision>
</link>

<link name="right_servo_mount_1">
  <inertial>
    <origin xyz="0.005194056332463476 -0.02008773112678317 0.02361159724929678" rpy="0 0 0"/>
    <mass value="0.14423806644766202"/>
    <inertia ixx="6.4e-05" iyy="5.5e-05" izz="5.3e-05" ixy="8e-06" iyz="-1e-06" ixz="-1e-06"/>
  </inertial>
  <visual>
    <origin xyz="0.079282 0.022679 -0.005" rpy="0 0 0"/>
    <geometry>
      <mesh filename="file://$(find leremix_description)/meshes/right_servo_mount_1.stl" scale="0.001 0.001 0.001"/>
    </geometry>
    <material name="silver"/>
  </visual>
  <collision>
    <origin xyz="0.079282 0.022679 -0.005" rpy="0 0 0"/>
    <geometry>
      <mesh filename="file://$(find leremix_description)/meshes/right_servo_mount_1.stl" scale="0.001 0.001 0.001"/>
    </geometry>
  </collision>
</link>

<link name="right_servo_1">
  <inertial>
    <origin xyz="-0.008868375307288748 -0.01694602119485174 0.0048189227637153095" rpy="0 0 0"/>
    <mass value="0.27778201352216375"/>
    <inertia ixx="6.3e-05" iyy="6.8e-05" izz="3.8e-05" ixy="-4e-06" iyz="-1e-06" ixz="-1e-06"/>
  </inertial>
  <visual>
    <origin xyz="0.069608 0.028345 -0.0235" rpy="0 0 0"/>
    <geometry>
      <mesh filename="file://$(find leremix_description)/meshes/right_servo_1.stl" scale="0.001 0.001 0.001"/>
    </geometry>
    <material name="silver"/>
  </visual>
  <collision>
    <origin xyz="0.069608 0.028345 -0.0235" rpy="0 0 0"/>
    <geometry>
      <mesh filename="file://$(find leremix_description)/meshes/right_servo_1.stl" scale="0.001 0.001 0.001"/>
    </geometry>
  </collision>
</link>

<link name="right_wheel_mount_1">
  <inertial>
    <origin xyz="-0.004783376671253933 -0.0027610611196918697 4.4100333345190035e-07" rpy="0 0 0"/>
    <mass value="0.1235708646349694"/>
    <inertia ixx="2.9e-05" iyy="2.2e-05" izz="1.8e-05" ixy="6e-06" iyz="-0.0" ixz="0.0"/>
  </inertial>
  <visual>
    <origin xyz="0.093574 0.054034 -0.015217" rpy="0 0 0"/>
    <geometry>
      <mesh filename="file://$(find leremix_description)/meshes/right_wheel_mount_1.stl" scale="0.001 0.001 0.001"/>
    </geometry>
    <material name="silver"/>
  </visual>
  <collision>
    <origin xyz="0.093574 0.054034 -0.015217" rpy="0 0 0"/>
    <geometry>
      <mesh filename="file://$(find leremix_description)/meshes/right_wheel_mount_1.stl" scale="0.001 0.001 0.001"/>
    </geometry>
  </collision>
</link>

<link name="back_servo_mount_1">
  <inertial>
    <origin xyz="0.02000689833996745 -0.015077228306122958 0.023640084058171418" rpy="0 0 0"/>
    <mass value="0.13962178083501173"/>
    <inertia ixx="4.7e-05" iyy="6.6e-05" izz="5e-05" ixy="0.0" iyz="2e-06" ixz="0.0"/>
  </inertial>
  <visual>
    <origin xyz="0.02 -0.1 -0.005" rpy="0 0 0"/>
    <geometry>
      <mesh filename="file://$(find leremix_description)/meshes/back_servo_mount_1.stl" scale="0.001 0.001 0.001"/>
    </geometry>
    <material name="silver"/>
  </visual>
  <collision>
    <origin xyz="0.02 -0.1 -0.005" rpy="0 0 0"/>
    <geometry>
      <mesh filename="file://$(find leremix_description)/meshes/back_servo_mount_1.stl" scale="0.001 0.001 0.001"/>
    </geometry>
  </collision>
</link>

<link name="left_servo_mount_1">
  <inertial>
    <origin xyz="-0.023060386227727117 -0.009786999823800477 0.023640084066370026" rpy="0 0 0"/>
    <mass value="0.13962178077674334"/>
    <inertia ixx="6.2e-05" iyy="5.2e-05" izz="5e-05" ixy="-8e-06" iyz="-1e-06" ixz="1e-06"/>
  </inertial>
  <visual>
    <origin xyz="-0.096603 0.032679 -0.005" rpy="0 0 0"/>
    <geometry>
      <mesh filename="file://$(find leremix_description)/meshes/left_servo_mount_1.stl" scale="0.001 0.001 0.001"/>
    </geometry>
    <material name="silver"/>
  </visual>
  <collision>
    <origin xyz="-0.096603 0.032679 -0.005" rpy="0 0 0"/>
    <geometry>
      <mesh filename="file://$(find leremix_description)/meshes/left_servo_mount_1.stl" scale="0.001 0.001 0.001"/>
    </geometry>
  </collision>
</link>

<link name="back_servo_1">
  <inertial>
    <origin xyz="-0.01025036665373221 0.01615304521052348 -0.019698114931770587" rpy="0 0 0"/>
    <mass value="0.2777820135235829"/>
    <inertia ixx="7e-05" iyy="6e-05" izz="3.8e-05" ixy="0.0" iyz="1e-06" ixz="-0.0"/>
  </inertial>
  <visual>
    <origin xyz="-0.010257 -0.074455 -0.047998" rpy="0 0 0"/>
    <geometry>
      <mesh filename="file://$(find leremix_description)/meshes/back_servo_1.stl" scale="0.001 0.001 0.001"/>
    </geometry>
    <material name="silver"/>
  </visual>
  <collision>
    <origin xyz="-0.010257 -0.074455 -0.047998" rpy="0 0 0"/>
    <geometry>
      <mesh filename="file://$(find leremix_description)/meshes/back_servo_1.stl" scale="0.001 0.001 0.001"/>
    </geometry>
  </collision>
</link>

<link name="right_wheel_1">
  <inertial>
    <origin xyz="-0.013315348435763222 -0.007687514715889375 3.760643008162562e-07" rpy="0 0 0"/>
    <mass value="1.3542854082324305"/>
    <inertia ixx="0.001683" iyy="0.00129" izz="0.001094" ixy="0.00034" iyz="0.0" ixz="-0.0"/>
  </inertial>
  <visual>
    <origin xyz="0.099788 0.057621 -0.015217" rpy="0 0 0"/>
    <geometry>
      <mesh filename="file://$(find leremix_description)/meshes/right_wheel_1.stl" scale="0.001 0.001 0.001"/>
    </geometry>
    <material name="silver"/>
  </visual>
  <collision>
    <origin xyz="0.099788 0.057621 -0.015217" rpy="0 0 0"/>
    <geometry>
      <mesh filename="file://$(find leremix_description)/meshes/right_wheel_1.stl" scale="0.001 0.001 0.001"/>
    </geometry>
  </collision>
</link>

<link name="back_wheel_mount_1">
  <inertial>
    <origin xyz="-3.718205031177714e-07 0.0055225174067364685 3.8436082915385694e-07" rpy="0 0 0"/>
    <mass value="0.1235708646349694"/>
    <inertia ixx="1.8e-05" iyy="3.3e-05" izz="1.8e-05" ixy="0.0" iyz="0.0" ixz="-0.0"/>
  </inertial>
  <visual>
    <origin xyz="-7e-06 -0.108055 -0.015198" rpy="0 0 0"/>
    <geometry>
      <mesh filename="file://$(find leremix_description)/meshes/back_wheel_mount_1.stl" scale="0.001 0.001 0.001"/>
    </geometry>
    <material name="silver"/>
  </visual>
  <collision>
    <origin xyz="-7e-06 -0.108055 -0.015198" rpy="0 0 0"/>
    <geometry>
      <mesh filename="file://$(find leremix_description)/meshes/back_wheel_mount_1.stl" scale="0.001 0.001 0.001"/>
    </geometry>
  </collision>
</link>

<link name="back_wheel_1">
  <inertial>
    <origin xyz="-4.805048774470552e-07 0.015374630356388475 4.613797826378413e-07" rpy="0 0 0"/>
    <mass value="1.3542854082324305"/>
    <inertia ixx="0.001094" iyy="0.00188" izz="0.001094" ixy="-0.0" iyz="0.0" ixz="0.0"/>
  </inertial>
  <visual>
    <origin xyz="-7e-06 -0.11523 -0.015198" rpy="0 0 0"/>
    <geometry>
      <mesh filename="file://$(find leremix_description)/meshes/back_wheel_1.stl" scale="0.001 0.001 0.001"/>
    </geometry>
    <material name="silver"/>
  </visual>
  <collision>
    <origin xyz="-7e-06 -0.11523 -0.015198" rpy="0 0 0"/>
    <geometry>
      <mesh filename="file://$(find leremix_description)/meshes/back_wheel_1.stl" scale="0.001 0.001 0.001"/>
    </geometry>
  </collision>
</link>

<link name="left_servo_1">
  <inertial>
    <origin xyz="0.008880833283207476 -0.01692483565245179 -0.01971552140381047" rpy="0 0 0"/>
    <mass value="0.27778201352216375"/>
    <inertia ixx="6.3e-05" iyy="6.8e-05" izz="3.8e-05" ixy="4e-06" iyz="-0.0" ixz="1e-06"/>
  </inertial>
  <visual>
    <origin xyz="-0.069602 0.028355 -0.047998" rpy="0 0 0"/>
    <geometry>
      <mesh filename="file://$(find leremix_description)/meshes/left_servo_1.stl" scale="0.001 0.001 0.001"/>
    </geometry>
    <material name="silver"/>
  </visual>
  <collision>
    <origin xyz="-0.069602 0.028355 -0.047998" rpy="0 0 0"/>
    <geometry>
      <mesh filename="file://$(find leremix_description)/meshes/left_servo_1.stl" scale="0.001 0.001 0.001"/>
    </geometry>
  </collision>
</link>

<link name="left_wheel_mount_1">
  <inertial>
    <origin xyz="0.0047831247862474 -0.002761267923911098 -3.1641937230098005e-09" rpy="0 0 0"/>
    <mass value="0.1235708646349694"/>
    <inertia ixx="2.9e-05" iyy="2.2e-05" izz="1.8e-05" ixy="-6e-06" iyz="0.0" ixz="0.0"/>
  </inertial>
  <visual>
    <origin xyz="-0.093603 0.053984 -0.015181" rpy="0 0 0"/>
    <geometry>
      <mesh filename="file://$(find leremix_description)/meshes/left_wheel_mount_1.stl" scale="0.001 0.001 0.001"/>
    </geometry>
    <material name="silver"/>
  </visual>
  <collision>
    <origin xyz="-0.093603 0.053984 -0.015181" rpy="0 0 0"/>
    <geometry>
      <mesh filename="file://$(find leremix_description)/meshes/left_wheel_mount_1.stl" scale="0.001 0.001 0.001"/>
    </geometry>
  </collision>
</link>

<link name="left_wheel_1">
  <inertial>
    <origin xyz="0.013314999193987778 -0.007687890146979293 1.1659539888610182e-07" rpy="0 0 0"/>
    <mass value="1.3542854082324305"/>
    <inertia ixx="0.001683" iyy="0.00129" izz="0.001094" ixy="-0.00034" iyz="0.0" ixz="0.0"/>
  </inertial>
  <visual>
    <origin xyz="-0.099817 0.057571 -0.015181" rpy="0 0 0"/>
    <geometry>
      <mesh filename="file://$(find leremix_description)/meshes/left_wheel_1.stl" scale="0.001 0.001 0.001"/>
    </geometry>
    <material name="silver"/>
  </visual>
  <collision>
    <origin xyz="-0.099817 0.057571 -0.015181" rpy="0 0 0"/>
    <geometry>
      <mesh filename="file://$(find leremix_description)/meshes/left_wheel_1.stl" scale="0.001 0.001 0.001"/>
    </geometry>
  </collision>
</link>

<link name="orin_1">
  <inertial>
    <origin xyz="0.04640281123350268 0.02998096631649686 0.010403847837754374" rpy="0 0 0"/>
    <mass value="0.4488469641841115"/>
    <inertia ixx="0.000254" iyy="0.000252" izz="0.000445" ixy="1e-05" iyz="3e-05" ixz="-3e-06"/>
  </inertial>
  <visual>
    <origin xyz="0.046136 -0.022 -0.0695" rpy="0 0 0"/>
    <geometry>
      <mesh filename="file://$(find leremix_description)/meshes/orin_1.stl" scale="0.001 0.001 0.001"/>
    </geometry>
    <material name="silver"/>
  </visual>
  <collision>
    <origin xyz="0.046136 -0.022 -0.0695" rpy="0 0 0"/>
    <geometry>
      <mesh filename="file://$(find leremix_description)/meshes/orin_1.stl" scale="0.001 0.001 0.001"/>
    </geometry>
  </collision>
</link>

<link name="orin_mount_1">
  <inertial>
    <origin xyz="0.039685457735832305 -0.0463864815527947 0.0016701033075652016" rpy="0 0 0"/>
    <mass value="0.0924663763130813"/>
    <inertia ixx="8.1e-05" iyy="0.00014" izz="0.000221" ixy="-1e-06" iyz="0.0" ixz="-0.0"/>
  </inertial>
  <visual>
    <origin xyz="0.04 -0.1 -0.0575" rpy="0 0 0"/>
    <geometry>
      <mesh filename="file://$(find leremix_description)/meshes/orin_mount_1.stl" scale="0.001 0.001 0.001"/>
    </geometry>
    <material name="silver"/>
  </visual>
  <collision>
    <origin xyz="0.04 -0.1 -0.0575" rpy="0 0 0"/>
    <geometry>
      <mesh filename="file://$(find leremix_description)/meshes/orin_mount_1.stl" scale="0.001 0.001 0.001"/>
    </geometry>
  </collision>
</link>

<link name="battery_stopper_1">
  <inertial>
    <origin xyz="-3.215223098096409e-05 -0.03000000089902556 0.0015000000000023484" rpy="0 0 0"/>
    <mass value="0.010467974999996237"/>
    <inertia ixx="4e-06" iyy="0.0" izz="4e-06" ixy="0.0" iyz="-0.0" ixz="0.0"/>
  </inertial>
  <visual>
    <origin xyz="-0.08 -0.06 -0.005" rpy="0 0 0"/>
    <geometry>
      <mesh filename="file://$(find leremix_description)/meshes/battery_stopper_1.stl" scale="0.001 0.001 0.001"/>
    </geometry>
    <material name="silver"/>
  </visual>
  <collision>
    <origin xyz="-0.08 -0.06 -0.005" rpy="0 0 0"/>
    <geometry>
      <mesh filename="file://$(find leremix_description)/meshes/battery_stopper_1.stl" scale="0.001 0.001 0.001"/>
    </geometry>
  </collision>
</link>

<link name="usb_pd_mount_1">
  <inertial>
    <origin xyz="0.0004325474904388216 -0.0099999999999838 0.001946020321486346" rpy="0 0 0"/>
    <mass value="0.0531436807920926"/>
    <inertia ixx="9e-06" iyy="1.1e-05" izz="2e-05" ixy="-0.0" iyz="0.0" ixz="-0.0"/>
  </inertial>
  <visual>
    <origin xyz="0.0 0.02 -0.005" rpy="0 0 0"/>
    <geometry>
      <mesh filename="file://$(find leremix_description)/meshes/usb_pd_mount_1.stl" scale="0.001 0.001 0.001"/>
    </geometry>
    <material name="silver"/>
  </visual>
  <collision>
    <origin xyz="0.0 0.02 -0.005" rpy="0 0 0"/>
    <geometry>
      <mesh filename="file://$(find leremix_description)/meshes/usb_pd_mount_1.stl" scale="0.001 0.001 0.001"/>
    </geometry>
  </collision>
</link>

<link name="arm_base_1">
  <inertial>
    <origin xyz="-0.04000319872849565 0.039749059642674334 0.02186552372353471" rpy="0 0 0"/>
    <mass value="1.2829039880853146"/>
    <inertia ixx="0.00136" iyy="0.001557" izz="0.001775" ixy="-0.0" iyz="-0.000249" ixz="0.0"/>
  </inertial>
  <visual>
    <origin xyz="-0.04 0.09 -0.0575" rpy="0 0 0"/>
    <geometry>
      <mesh filename="file://$(find leremix_description)/meshes/arm_base_1.stl" scale="0.001 0.001 0.001"/>
    </geometry>
    <material name="silver"/>
  </visual>
  <collision>
    <origin xyz="-0.04 0.09 -0.0575" rpy="0 0 0"/>
    <geometry>
      <mesh filename="file://$(find leremix_description)/meshes/arm_base_1.stl" scale="0.001 0.001 0.001"/>
    </geometry>
  </collision>
</link>

<link name="imu_1">
  <inertial>
    <origin xyz="-0.010795000000004773 -0.0076200000000198305 -0.0008833333333333887" rpy="0 0 0"/>
    <mass value="0.007606013634323334"/>
    <inertia ixx="0.0" iyy="0.0" izz="1e-06" ixy="-0.0" iyz="-0.0" ixz="-0.0"/>
  </inertial>
  <visual>
    <origin xyz="-0.01016 -0.0076 -0.0635" rpy="0 0 0"/>
    <geometry>
      <mesh filename="file://$(find leremix_description)/meshes/imu_1.stl" scale="0.001 0.001 0.001"/>
    </geometry>
    <material name="silver"/>
  </visual>
  <collision>
    <origin xyz="-0.01016 -0.0076 -0.0635" rpy="0 0 0"/>
    <geometry>
      <mesh filename="file://$(find leremix_description)/meshes/imu_1.stl" scale="0.001 0.001 0.001"/>
    </geometry>
  </collision>
</link>

<link name="imu_mount_1">
  <inertial>
    <origin xyz="-0.020000000000006752 -9.636735853746358e-15 0.0011228233092131293" rpy="0 0 0"/>
    <mass value="0.011661793388699252"/>
    <inertia ixx="0.0" iyy="1e-06" izz="2e-06" ixy="-0.0" iyz="-0.0" ixz="-0.0"/>
  </inertial>
  <visual>
    <origin xyz="-0.02 0.0 -0.0575" rpy="0 0 0"/>
    <geometry>
      <mesh filename="file://$(find leremix_description)/meshes/imu_mount_1.stl" scale="0.001 0.001 0.001"/>
    </geometry>
    <material name="silver"/>
  </visual>
  <collision>
    <origin xyz="-0.02 0.0 -0.0575" rpy="0 0 0"/>
    <geometry>
      <mesh filename="file://$(find leremix_description)/meshes/imu_mount_1.stl" scale="0.001 0.001 0.001"/>
    </geometry>
  </collision>
</link>

<link name="hex_1__1__1">
  <inertial>
    <origin xyz="-3.2115976544844216e-13 -1.5265566588595902e-16 0.02274999999999771" rpy="0 0 0"/>
    <mass value="0.010098885204413197"/>
    <inertia ixx="2e-06" iyy="2e-06" izz="0.0" ixy="-0.0" iyz="-0.0" ixz="0.0"/>
  </inertial>
  <visual>
    <origin xyz="0.08 -0.1 -0.0575" rpy="0 0 0"/>
    <geometry>
      <mesh filename="file://$(find leremix_description)/meshes/hex_1__1__1.stl" scale="0.001 0.001 0.001"/>
    </geometry>
    <material name="silver"/>
  </visual>
  <collision>
    <origin xyz="0.08 -0.1 -0.0575" rpy="0 0 0"/>
    <geometry>
      <mesh filename="file://$(find leremix_description)/meshes/hex_1__1__1.stl" scale="0.001 0.001 0.001"/>
    </geometry>
  </collision>
</link>

<link name="just_the_tower_v1_1">
  <inertial>
    <origin xyz="-0.039563575787050026 0.04049608100146749 0.0846718390764672" rpy="0 0 0"/>
    <mass value="1.0410314460711032"/>
    <inertia ixx="0.004248" iyy="0.004373" izz="0.00092" ixy="-1e-06" iyz="-0.000197" ixz="-2.3e-05"/>
  </inertial>
  <visual>
    <origin xyz="-0.04 -0.04 -0.108" rpy="0 0 0"/>
    <geometry>
      <mesh filename="file://$(find leremix_description)/meshes/just_the_tower_v1_1.stl" scale="0.001 0.001 0.001"/>
    </geometry>
    <material name="silver"/>
  </visual>
  <collision>
    <origin xyz="-0.04 -0.04 -0.108" rpy="0 0 0"/>
    <geometry>
      <mesh filename="file://$(find leremix_description)/meshes/just_the_tower_v1_1.stl" scale="0.001 0.001 0.001"/>
    </geometry>
  </collision>
</link>

<link name="support_v1_1">
  <inertial>
    <origin xyz="-0.03235025944360012 -0.014635968357238766 0.024780277739785972" rpy="0 0 0"/>
    <mass value="0.27772651196367043"/>
    <inertia ixx="0.00017" iyy="0.000201" izz="0.000112" ixy="-0.0" iyz="-2.1e-05" ixz="-0.0"/>
  </inertial>
  <visual>
    <origin xyz="-0.033358 -0.105 -0.280565" rpy="0 0 0"/>
    <geometry>
      <mesh filename="file://$(find leremix_description)/meshes/support_v1_1.stl" scale="0.001 0.001 0.001"/>
    </geometry>
    <material name="silver"/>
  </visual>
  <collision>
    <origin xyz="-0.033358 -0.105 -0.280565" rpy="0 0 0"/>
    <geometry>
      <mesh filename="file://$(find leremix_description)/meshes/support_v1_1.stl" scale="0.001 0.001 0.001"/>
    </geometry>
  </collision>
</link>

<link name="head_camera_1">
  <inertial>
    <origin xyz="-0.02138780851329633 -0.012449722289258931 8.215900246144603e-05" rpy="0 0 0"/>
    <mass value="0.35928853728306875"/>
    <inertia ixx="3.3e-05" iyy="0.000217" izz="0.000219" ixy="-3e-06" iyz="-0.0" ixz="0.0"/>
  </inertial>
  <visual>
    <origin xyz="-0.023758 -0.016731 -0.413674" rpy="0 0 0"/>
    <geometry>
      <mesh filename="file://$(find leremix_description)/meshes/head_camera_1.stl" scale="0.001 0.001 0.001"/>
    </geometry>
    <material name="silver"/>
  </visual>
  <collision>
    <origin xyz="-0.023758 -0.016731 -0.413674" rpy="0 0 0"/>
    <geometry>
      <mesh filename="file://$(find leremix_description)/meshes/head_camera_1.stl" scale="0.001 0.001 0.001"/>
    </geometry>
  </collision>
</link>

<link name="hex_1_1">
  <inertial>
    <origin xyz="-3.2286673334880334e-13 -3.552713678800501e-15 0.02274999999999778" rpy="0 0 0"/>
    <mass value="0.010098885204413197"/>
    <inertia ixx="2e-06" iyy="2e-06" izz="0.0" ixy="-0.0" iyz="-0.0" ixz="0.0"/>
  </inertial>
  <visual>
    <origin xyz="0.1 -0.04 -0.0575" rpy="0 0 0"/>
    <geometry>
      <mesh filename="file://$(find leremix_description)/meshes/hex_1_1.stl" scale="0.001 0.001 0.001"/>
    </geometry>
    <material name="silver"/>
  </visual>
  <collision>
    <origin xyz="0.1 -0.04 -0.0575" rpy="0 0 0"/>
    <geometry>
      <mesh filename="file://$(find leremix_description)/meshes/hex_1_1.stl" scale="0.001 0.001 0.001"/>
    </geometry>
  </collision>
</link>

<link name="hex_2_1">
  <inertial>
    <origin xyz="-3.156225281131242e-13 -5.259681579161679e-15 0.022750000000000013" rpy="0 0 0"/>
    <mass value="0.010098885204413197"/>
    <inertia ixx="2e-06" iyy="2e-06" izz="0.0" ixy="-0.0" iyz="0.0" ixz="0.0"/>
  </inertial>
  <visual>
    <origin xyz="-0.1 -0.04 -0.0575" rpy="0 0 0"/>
    <geometry>
      <mesh filename="file://$(find leremix_description)/meshes/hex_2_1.stl" scale="0.001 0.001 0.001"/>
    </geometry>
    <material name="silver"/>
  </visual>
  <collision>
    <origin xyz="-0.1 -0.04 -0.0575" rpy="0 0 0"/>
    <geometry>
      <mesh filename="file://$(find leremix_description)/meshes/hex_2_1.stl" scale="0.001 0.001 0.001"/>
    </geometry>
  </collision>
</link>

<link name="hex_1__1___1__1">
  <inertial>
    <origin xyz="-3.167743845011728e-13 -2.9837243786801082e-15 0.022749999999999417" rpy="0 0 0"/>
    <mass value="0.010098885204413197"/>
    <inertia ixx="2e-06" iyy="2e-06" izz="0.0" ixy="-0.0" iyz="-0.0" ixz="0.0"/>
  </inertial>
  <visual>
    <origin xyz="-0.08 -0.1 -0.0575" rpy="0 0 0"/>
    <geometry>
      <mesh filename="file://$(find leremix_description)/meshes/hex_1__1___1__1.stl" scale="0.001 0.001 0.001"/>
    </geometry>
    <material name="silver"/>
  </visual>
  <collision>
    <origin xyz="-0.08 -0.1 -0.0575" rpy="0 0 0"/>
    <geometry>
      <mesh filename="file://$(find leremix_description)/meshes/hex_1__1___1__1.stl" scale="0.001 0.001 0.001"/>
    </geometry>
  </collision>
</link>

<link name="last_floor_v1_1">
  <inertial>
    <origin xyz="0.07999999999996689 -0.04424083204691201 0.002499999999998004" rpy="0 0 0"/>
    <mass value="0.7574741481613873"/>
    <inertia ixx="0.000555" iyy="0.00284" izz="0.003391" ixy="0.0" iyz="-0.0" ixz="0.0"/>
  </inertial>
  <visual>
    <origin xyz="0.08 -0.1 -0.103" rpy="0 0 0"/>
    <geometry>
      <mesh filename="file://$(find leremix_description)/meshes/last_floor_v1_1.stl" scale="0.001 0.001 0.001"/>
    </geometry>
    <material name="silver"/>
  </visual>
  <collision>
    <origin xyz="0.08 -0.1 -0.103" rpy="0 0 0"/>
    <geometry>
      <mesh filename="file://$(find leremix_description)/meshes/last_floor_v1_1.stl" scale="0.001 0.001 0.001"/>
    </geometry>
  </collision>
</link>

<link name="front_cam_support_1">
  <inertial>
    <origin xyz="0.03999999999999915 -0.0021558238546785374 0.02345182131201227" rpy="0 0 0"/>
    <mass value="0.13844922782782626"/>
    <inertia ixx="2.6e-05" iyy="0.000146" izz="0.000121" ixy="-0.0" iyz="0.0" ixz="0.0"/>
  </inertial>
  <visual>
    <origin xyz="0.04 0.1 -0.005" rpy="0 0 0"/>
    <geometry>
      <mesh filename="file://$(find leremix_description)/meshes/front_cam_support_1.stl" scale="0.001 0.001 0.001"/>
    </geometry>
    <material name="silver"/>
  </visual>
  <collision>
    <origin xyz="0.04 0.1 -0.005" rpy="0 0 0"/>
    <geometry>
      <mesh filename="file://$(find leremix_description)/meshes/front_cam_support_1.stl" scale="0.001 0.001 0.001"/>
    </geometry>
  </collision>
</link>

<link name="front_camera_1">
  <inertial>
    <origin xyz="0.023612368948277514 -0.01245033745489689 -2.7969539088176093e-05" rpy="0 0 0"/>
    <mass value="0.35928853728306875"/>
    <inertia ixx="3.3e-05" iyy="0.000217" izz="0.000219" ixy="-3e-06" iyz="-0.0" ixz="-0.0"/>
  </inertial>
  <visual>
    <origin xyz="0.0225 0.105 -0.028475" rpy="0 0 0"/>
    <geometry>
      <mesh filename="file://$(find leremix_description)/meshes/front_camera_1.stl" scale="0.001 0.001 0.001"/>
    </geometry>
    <material name="silver"/>
  </visual>
  <collision>
    <origin xyz="0.0225 0.105 -0.028475" rpy="0 0 0"/>
    <geometry>
      <mesh filename="file://$(find leremix_description)/meshes/front_camera_1.stl" scale="0.001 0.001 0.001"/>
    </geometry>
  </collision>
</link>

<link name="hex_3_1">
  <inertial>
    <origin xyz="-3.1520619447888976e-13 -2.914335439641036e-15 0.0237499999999998" rpy="0 0 0"/>
    <mass value="0.010542792246365427"/>
    <inertia ixx="2e-06" iyy="2e-06" izz="0.0" ixy="-0.0" iyz="-0.0" ixz="0.0"/>
  </inertial>
  <visual>
    <origin xyz="-0.1 -0.06 -0.005" rpy="0 0 0"/>
    <geometry>
      <mesh filename="file://$(find leremix_description)/meshes/hex_3_1.stl" scale="0.001 0.001 0.001"/>
    </geometry>
    <material name="silver"/>
  </visual>
  <collision>
    <origin xyz="-0.1 -0.06 -0.005" rpy="0 0 0"/>
    <geometry>
      <mesh filename="file://$(find leremix_description)/meshes/hex_3_1.stl" scale="0.001 0.001 0.001"/>
    </geometry>
  </collision>
</link>

<link name="hex_4_1">
  <inertial>
    <origin xyz="-3.117783808903596e-13 1.061650767297806e-15 0.02374999999999943" rpy="0 0 0"/>
    <mass value="0.010542792246365427"/>
    <inertia ixx="2e-06" iyy="2e-06" izz="0.0" ixy="-0.0" iyz="-0.0" ixz="0.0"/>
  </inertial>
  <visual>
    <origin xyz="0.1 -0.06 -0.005" rpy="0 0 0"/>
    <geometry>
      <mesh filename="file://$(find leremix_description)/meshes/hex_4_1.stl" scale="0.001 0.001 0.001"/>
    </geometry>
    <material name="silver"/>
  </visual>
  <collision>
    <origin xyz="0.1 -0.06 -0.005" rpy="0 0 0"/>
    <geometry>
      <mesh filename="file://$(find leremix_description)/meshes/hex_4_1.stl" scale="0.001 0.001 0.001"/>
    </geometry>
  </collision>
</link>

<link name="upper_floor_1">
  <inertial>
    <origin xyz="-0.09996896829294144 -0.053943038334943474 0.002499999999999253" rpy="0 0 0"/>
    <mass value="1.5373763767670563"/>
    <inertia ixx="0.005051" iyy="0.005253" izz="0.010298" ixy="3e-06" iyz="-0.0" ixz="0.0"/>
  </inertial>
  <visual>
    <origin xyz="-0.1 -0.06 -0.0525" rpy="0 0 0"/>
    <geometry>
      <mesh filename="file://$(find leremix_description)/meshes/upper_floor_1.stl" scale="0.001 0.001 0.001"/>
    </geometry>
    <material name="silver"/>
  </visual>
  <collision>
    <origin xyz="-0.1 -0.06 -0.0525" rpy="0 0 0"/>
    <geometry>
      <mesh filename="file://$(find leremix_description)/meshes/upper_floor_1.stl" scale="0.001 0.001 0.001"/>
    </geometry>
  </collision>
</link>

<link name="pan_link_1">
  <inertial>
    <origin xyz="-0.000271745496464291 -0.03155586642635756 -0.00854045842122414" rpy="0 0 0"/>
    <mass value="0.5385469320676795"/>
    <inertia ixx="0.000375" iyy="0.000341" izz="0.000154" ixy="1e-06" iyz="3.6e-05" ixz="3e-06"/>
  </inertial>
  <visual>
    <origin xyz="-0.001258 -0.0591 -0.333906" rpy="0 0 0"/>
    <geometry>
      <mesh filename="file://$(find leremix_description)/meshes/pan_link_1.stl" scale="0.001 0.001 0.001"/>
    </geometry>
    <material name="silver"/>
  </visual>
  <collision>
    <origin xyz="-0.001258 -0.0591 -0.333906" rpy="0 0 0"/>
    <geometry>
      <mesh filename="file://$(find leremix_description)/meshes/pan_link_1.stl" scale="0.001 0.001 0.001"/>
    </geometry>
  </collision>
</link>

<link name="tilt_servo_1">
  <inertial>
    <origin xyz="-0.016027240855204114 0.010250000006736436 0.019999018791922563" rpy="0 0 0"/>
    <mass value="0.2843033831904074"/>
    <inertia ixx="6.2e-05" iyy="7.3e-05" izz="4e-05" ixy="-0.0" iyz="0.0" ixz="1e-06"/>
  </inertial>
  <visual>
    <origin xyz="-0.017558 -0.01825 -0.354306" rpy="0 0 0"/>
    <geometry>
      <mesh filename="file://$(find leremix_description)/meshes/tilt_servo_1.stl" scale="0.001 0.001 0.001"/>
    </geometry>
    <material name="silver"/>
  </visual>
  <collision>
    <origin xyz="-0.017558 -0.01825 -0.354306" rpy="0 0 0"/>
    <geometry>
      <mesh filename="file://$(find leremix_description)/meshes/tilt_servo_1.stl" scale="0.001 0.001 0.001"/>
    </geometry>
  </collision>
</link>

<link name="tilt_link_cover_1">
  <inertial>
    <origin xyz="-0.015350382695118946 -0.01100576877177608 0.0011417813907908525" rpy="0 0 0"/>
    <mass value="0.10853073755546007"/>
    <inertia ixx="2.7e-05" iyy="4.6e-05" izz="5.8e-05" ixy="0.0" iyz="0.0" ixz="-0.0"/>
  </inertial>
  <visual>
    <origin xyz="-0.017558 -0.03875 -0.354306" rpy="0 0 0"/>
    <geometry>
      <mesh filename="file://$(find leremix_description)/meshes/tilt_link_cover_1.stl" scale="0.001 0.001 0.001"/>
    </geometry>
    <material name="silver"/>
  </visual>
  <collision>
    <origin xyz="-0.017558 -0.03875 -0.354306" rpy="0 0 0"/>
    <geometry>
      <mesh filename="file://$(find leremix_description)/meshes/tilt_link_cover_1.stl" scale="0.001 0.001 0.001"/>
    </geometry>
  </collision>
</link>

<link name="realsense_support_v1_1">
  <inertial>
    <origin xyz="0.3867987611840498 -0.029386763368479594 0.007036638529899886" rpy="0 0 0"/>
    <mass value="0.22381597612221305"/>
    <inertia ixx="4.8e-05" iyy="0.000145" izz="0.00012" ixy="-0.0" iyz="3e-06" ixz="0.0"/>
  </inertial>
  <visual>
    <origin xyz="0.385448 -0.057 -0.394564" rpy="0 0 0"/>
    <geometry>
      <mesh filename="file://$(find leremix_description)/meshes/realsense_support_v1_1.stl" scale="0.001 0.001 0.001"/>
    </geometry>
    <material name="silver"/>
  </visual>
  <collision>
    <origin xyz="0.385448 -0.057 -0.394564" rpy="0 0 0"/>
    <geometry>
      <mesh filename="file://$(find leremix_description)/meshes/realsense_support_v1_1.stl" scale="0.001 0.001 0.001"/>
    </geometry>
  </collision>
</link>

<link name="pan_servo__1__1">
  <inertial>
    <origin xyz="-0.010250175923727 -0.016199027563226193 -0.01577294384657063" rpy="0 0 0"/>
    <mass value="0.2843033831904074"/>
    <inertia ixx="7.3e-05" iyy="4e-05" izz="6.2e-05" ixy="-0.0" iyz="1e-06" ixz="0.0"/>
  </inertial>
  <visual>
    <origin xyz="-0.011508 -0.0881 -0.331106" rpy="0 0 0"/>
    <geometry>
      <mesh filename="file://$(find leremix_description)/meshes/pan_servo__1__1.stl" scale="0.001 0.001 0.001"/>
    </geometry>
    <material name="silver"/>
  </visual>
  <collision>
    <origin xyz="-0.011508 -0.0881 -0.331106" rpy="0 0 0"/>
    <geometry>
      <mesh filename="file://$(find leremix_description)/meshes/pan_servo__1__1.stl" scale="0.001 0.001 0.001"/>
    </geometry>
  </collision>
</link>

<joint name="Rigid 44" type="fixed">
  <origin xyz="-0.05025 0.045652 0.0278" rpy="0 0 0"/>
  <parent link="arm_base_1"/>
  <child link="arm_base_rotation_servo_1"/>
</joint>

<joint name="1" type="continuous">
  <origin xyz="0.01025 -0.0328 0.0346" rpy="0 0 0"/>
  <parent link="arm_base_rotation_servo_1"/>
  <child link="arm_base_rotation_link_1"/>
  <axis xyz="-0.0 -0.0 -1.0"/>
</joint>

<joint name="Rigid 46" type="fixed">
  <origin xyz="-0.023 -0.04085 0.0232" rpy="0 0 0"/>
  <parent link="arm_base_rotation_link_1"/>
  <child link="arm_base_rotation_link_cover_1"/>
</joint>

<joint name="Rigid 48" type="fixed">
  <origin xyz="0.0163 -0.04085 0.0194" rpy="0 0 0"/>
  <parent link="arm_base_rotation_link_1"/>
  <child link="arm_shoulder_servo_1"/>
</joint>

<joint name="2" type="continuous">
  <origin xyz="-0.0346 0.01025 0.0328" rpy="0 0 0"/>
  <parent link="arm_shoulder_servo_1"/>
  <child link="arm_shoulder_link_1"/>
  <axis xyz="-1.0 0.0 -0.0"/>
</joint>

<joint name="Rigid 50" type="fixed">
  <origin xyz="0.0361 0.097591 -0.031119" rpy="0 0 0"/>
  <parent link="arm_shoulder_link_1"/>
  <child link="arm_elbow_servo_1"/>
</joint>

<joint name="3" type="continuous">
  <origin xyz="-0.0346 0.01839 0.02903" rpy="0 0 0"/>
  <parent link="arm_elbow_servo_1"/>
  <child link="arm_elbow_link_1"/>
  <axis xyz="-1.0 0.0 -0.0"/>
</joint>

<joint name="Rigid 52" type="fixed">
  <origin xyz="0.0361 -0.091598 0.04978" rpy="0 0 0"/>
  <parent link="arm_elbow_link_1"/>
  <child link="arm_wrist_tilt_servo_1"/>
</joint>

<joint name="4" type="continuous">
  <origin xyz="-0.0346 -0.034335 -0.001411" rpy="0 0 0"/>
  <parent link="arm_wrist_tilt_servo_1"/>
  <child link="arm_wrist_link_1"/>
  <axis xyz="-1.0 0.0 -0.0"/>
</joint>

<joint name="arm_wrist_roll_solid" type="fixed">
  <origin xyz="-0.0089 -0.059192 -0.000469" rpy="0 0 0"/>
  <parent link="arm_wrist_link_1"/>
  <child link="arm_wrist_roll_servo_1"/>
</joint>

<joint name="5" type="continuous">
  <origin xyz="0.029 -0.000899 -0.010588" rpy="0 0 0"/>
  <parent link="arm_wrist_roll_servo_1"/>
  <child link="arm_gripper_1"/>
  <axis xyz="-0.0 -0.983492 -0.180954"/>
</joint>

<joint name="Rigid 56" type="fixed">
  <origin xyz="0.006032 -0.009096 -0.021717" rpy="0 0 0"/>
  <parent link="arm_gripper_1"/>
  <child link="arm_gripper_servo_1"/>
</joint>

<joint name="6" type="continuous">
  <origin xyz="-0.017389 -0.018113 0.041804" rpy="0 0 0"/>
  <parent link="arm_gripper_servo_1"/>
  <child link="arm_jaw_1"/>
  <axis xyz="0.375894 -0.167683 0.911365"/>
</joint>

<joint name="Rigid 75" type="fixed">
  <origin xyz="-0.079282 -0.022679 0.005" rpy="0 0 0"/>
  <parent link="base_link"/>
  <child link="right_servo_mount_1"/>
</joint>

<joint name="Rigid 76" type="fixed">
  <origin xyz="0.009674 -0.005666 0.0185" rpy="0 0 0"/>
  <parent link="right_servo_mount_1"/>
  <child link="right_servo_1"/>
</joint>

<joint name="wheel2_rotation" type="continuous">
  <origin xyz="-0.023966 -0.025689 -0.008283" rpy="0 0 0"/>
  <parent link="right_servo_1"/>
  <child link="right_wheel_mount_1"/>
  <axis xyz="0.866025 0.5 -0.0"/>
</joint>

<joint name="Rigid 79" type="fixed">
  <origin xyz="-0.02 0.1 0.005" rpy="0 0 0"/>
  <parent link="base_link"/>
  <child link="back_servo_mount_1"/>
</joint>

<joint name="Rigid 80" type="fixed">
  <origin xyz="0.096603 -0.032679 0.005" rpy="0 0 0"/>
  <parent link="base_link"/>
  <child link="left_servo_mount_1"/>
</joint>

<joint name="Rigid 81" type="fixed">
  <origin xyz="0.030257 -0.025545 0.042998" rpy="0 0 0"/>
  <parent link="back_servo_mount_1"/>
  <child link="back_servo_1"/>
</joint>

<joint name="Rigid 82" type="fixed">
  <origin xyz="-0.006214 -0.003587 0.0" rpy="0 0 0"/>
  <parent link="right_wheel_mount_1"/>
  <child link="right_wheel_1"/>
</joint>

<joint name="wheel1_rotation" type="continuous">
  <origin xyz="-0.01025 0.0336 -0.0328" rpy="0 0 0"/>
  <parent link="back_servo_1"/>
  <child link="back_wheel_mount_1"/>
  <axis xyz="-0.0 1.0 0.0"/>
</joint>

<joint name="Rigid 85" type="fixed">
  <origin xyz="0.0 0.007175 0.0" rpy="0 0 0"/>
  <parent link="back_wheel_mount_1"/>
  <child link="back_wheel_1"/>
</joint>

<joint name="Rigid 86" type="fixed">
  <origin xyz="-0.027001 0.004324 0.042998" rpy="0 0 0"/>
  <parent link="left_servo_mount_1"/>
  <child link="left_servo_1"/>
</joint>

<joint name="wheel3_rotation" type="continuous">
  <origin xyz="0.024001 -0.025629 -0.032817" rpy="0 0 0"/>
  <parent link="left_servo_1"/>
  <child link="left_wheel_mount_1"/>
  <axis xyz="-0.866025 0.5 -0.0"/>
</joint>

<joint name="Rigid 88" type="fixed">
  <origin xyz="0.006214 -0.003587 0.0" rpy="0 0 0"/>
  <parent link="left_wheel_mount_1"/>
  <child link="left_wheel_1"/>
</joint>

<joint name="Rigid 90" type="fixed">
  <origin xyz="-0.006136 -0.078 0.012" rpy="0 0 0"/>
  <parent link="orin_mount_1"/>
  <child link="orin_1"/>
</joint>

<joint name="Rigid 91" type="fixed">
  <origin xyz="-0.14 0.04 0.005" rpy="0 0 0"/>
  <parent link="upper_floor_1"/>
  <child link="orin_mount_1"/>
</joint>

<joint name="Rigid 92" type="fixed">
  <origin xyz="0.08 0.06 0.005" rpy="0 0 0"/>
  <parent link="base_link"/>
  <child link="battery_stopper_1"/>
</joint>

<joint name="Rigid 100" type="fixed">
  <origin xyz="0.0 -0.02 0.005" rpy="0 0 0"/>
  <parent link="base_link"/>
  <child link="usb_pd_mount_1"/>
</joint>

<joint name="Rigid 103" type="fixed">
  <origin xyz="-0.06 -0.15 0.005" rpy="0 0 0"/>
  <parent link="upper_floor_1"/>
  <child link="arm_base_1"/>
</joint>

<joint name="Rigid 115" type="fixed">
  <origin xyz="-0.00984 0.0076 0.006" rpy="0 0 0"/>
  <parent link="imu_mount_1"/>
  <child link="imu_1"/>
</joint>

<joint name="Rigid 117" type="fixed">
  <origin xyz="-0.08 -0.06 0.005" rpy="0 0 0"/>
  <parent link="upper_floor_1"/>
  <child link="imu_mount_1"/>
</joint>

<joint name="Rigid 147" type="fixed">
  <origin xyz="-0.18 0.04 0.005" rpy="0 0 0"/>
  <parent link="upper_floor_1"/>
  <child link="hex_1__1__1"/>
</joint>

<joint name="Rigid 156" type="fixed">
  <origin xyz="0.12 -0.06 0.005" rpy="0 0 0"/>
  <parent link="last_floor_v1_1"/>
  <child link="just_the_tower_v1_1"/>
</joint>

<joint name="Rigid 157" type="fixed">
  <origin xyz="-0.006642 0.065 0.172565" rpy="0 0 0"/>
  <parent link="just_the_tower_v1_1"/>
  <child link="support_v1_1"/>
</joint>

<joint name="Rigid 165" type="fixed">
  <origin xyz="0.409206 -0.040269 0.01911" rpy="0 0 0"/>
  <parent link="realsense_support_v1_1"/>
  <child link="head_camera_1"/>
</joint>

<joint name="Rigid 166" type="fixed">
  <origin xyz="-0.2 -0.02 0.005" rpy="0 0 0"/>
  <parent link="upper_floor_1"/>
  <child link="hex_1_1"/>
</joint>

<joint name="Rigid 167" type="fixed">
  <origin xyz="0.0 -0.02 0.005" rpy="0 0 0"/>
  <parent link="upper_floor_1"/>
  <child link="hex_2_1"/>
</joint>

<joint name="Rigid 168" type="fixed">
  <origin xyz="-0.02 0.04 0.005" rpy="0 0 0"/>
  <parent link="upper_floor_1"/>
  <child link="hex_1__1___1__1"/>
</joint>

<joint name="Rigid 169" type="fixed">
  <origin xyz="0.0 0.0 0.0455" rpy="0 0 0"/>
  <parent link="hex_1__1__1"/>
  <child link="last_floor_v1_1"/>
</joint>

<joint name="Rigid 170" type="fixed">
  <origin xyz="-0.04 -0.1 0.005" rpy="0 0 0"/>
  <parent link="base_link"/>
  <child link="front_cam_support_1"/>
</joint>

<joint name="Rigid 171" type="fixed">
  <origin xyz="0.0175 -0.005 0.023475" rpy="0 0 0"/>
  <parent link="front_cam_support_1"/>
  <child link="front_camera_1"/>
</joint>

<joint name="Rigid 172" type="fixed">
  <origin xyz="0.1 0.06 0.005" rpy="0 0 0"/>
  <parent link="base_link"/>
  <child link="hex_3_1"/>
</joint>

<joint name="Rigid 173" type="fixed">
  <origin xyz="-0.1 0.06 0.005" rpy="0 0 0"/>
  <parent link="base_link"/>
  <child link="hex_4_1"/>
</joint>

<joint name="Rigid 174" type="fixed">
  <origin xyz="0.0 0.0 0.0475" rpy="0 0 0"/>
  <parent link="hex_3_1"/>
  <child link="upper_floor_1"/>
</joint>

<joint name="camera_pan" type="continuous">
  <origin xyz="-0.01025 -0.029 0.0028" rpy="0 0 0"/>
  <parent link="pan_servo__1__1"/>
  <child link="pan_link_1"/>
  <axis xyz="-0.0 -0.0 -1.0"/>
</joint>

<joint name="Rigid 176" type="fixed">
  <origin xyz="0.0163 -0.04085 0.0204" rpy="0 0 0"/>
  <parent link="pan_link_1"/>
  <child link="tilt_servo_1"/>
</joint>

<joint name="Rigid 177" type="fixed">
  <origin xyz="0.0 0.0205 0.0" rpy="0 0 0"/>
  <parent link="tilt_servo_1"/>
  <child link="tilt_link_cover_1"/>
</joint>

<joint name="camera_tilt" type="continuous">
  <origin xyz="-0.403006 0.03875 0.040258" rpy="0 0 0"/>
  <parent link="tilt_servo_1"/>
  <child link="realsense_support_v1_1"/>
  <axis xyz="1.0 -0.0 0.0"/>
</joint>

<joint name="Rigid 179" type="fixed">
  <origin xyz="-0.02185 -0.0169 0.050541" rpy="0 0 0"/>
  <parent link="support_v1_1"/>
  <child link="pan_servo__1__1"/>
</joint>


<!-- ros2_control hardware interface
<ros2_control name="leremix_hardware" type="system">
  <hardware>
    <plugin>leremix_control_plugin/Esp32SystemTopic</plugin>
    <param name="base_cmd_topic">/esp32/base_cmd</param>
    <param name="arm_cmd_topic">/esp32/arm_cmd</param>
    <param name="state_topic">/esp32/joint_states</param>
    <param name="publish_if_unchanged">true</param>
  </hardware>
  

  <joint name="back_motor_rotation">
    <command_interface name="velocity"/>
    <state_interface name="position"/>
    <state_interface name="velocity"/>
  </joint>
  <joint name="left_motor_rotation">
    <command_interface name="velocity"/>
    <state_interface name="position"/>
    <state_interface name="velocity"/>
  </joint>
  <joint name="right_motor_rotation">
    <command_interface name="velocity"/>
    <state_interface name="position"/>
    <state_interface name="velocity"/>
  </joint>
  
  <joint name="1">
    <command_interface name="position"/>
    <state_interface name="position"/>
  </joint>
  <joint name="2">
    <command_interface name="position"/>
    <state_interface name="position"/>
  </joint>
  <joint name="3">
    <command_interface name="position"/>
    <state_interface name="position"/>
  </joint>
  <joint name="4">
    <command_interface name="position"/>
    <state_interface name="position"/>
  </joint>
  <joint name="5">
    <command_interface name="position"/>
    <state_interface name="position"/>
  </joint>
  <joint name="6">
    <command_interface name="position"/>
    <state_interface name="position"/>
  </joint>
  <joint name="camera_tilt">
    <command_interface name="position"/>
    <state_interface name="position"/>
  </joint>
</ros2_control>
-->

</robot>